<sdf version='1.6'>
  <world name='default'>
    <light name='sun' type='directional'>
      <cast_shadows>1</cast_shadows>
      <pose frame=''>0 0 10 0 -0 0</pose>
      <diffuse>0.8 0.8 0.8 1</diffuse>
      <specular>0.2 0.2 0.2 1</specular>
      <attenuation>
        <range>1000</range>
        <constant>0.9</constant>
        <linear>0.01</linear>
        <quadratic>0.001</quadratic>
      </attenuation>
      <direction>-0.5 0.1 -0.9</direction>
    </light>
    <model name='ground_plane'>
      <static>1</static>
      <link name='link'>
        <collision name='collision'>
          <geometry>
            <plane>
              <normal>0 0 1</normal>
              <size>100 100</size>
            </plane>
          </geometry>
          <surface>
            <contact>
              <collide_bitmask>65535</collide_bitmask>
              <ode/>
            </contact>
            <friction>
              <ode>
                <mu>100</mu>
                <mu2>50</mu2>
              </ode>
              <torsional>
                <ode/>
              </torsional>
            </friction>
            <bounce/>
          </surface>
          <max_contacts>10</max_contacts>
        </collision>
        <visual name='visual'>
          <cast_shadows>0</cast_shadows>
          <geometry>
            <plane>
              <normal>0 0 1</normal>
              <size>100 100</size>
            </plane>
          </geometry>
          <material>
            <script>
              <uri>file://media/materials/scripts/gazebo.material</uri>
              <name>Gazebo/Grey</name>
            </script>
          </material>
        </visual>
        <self_collide>0</self_collide>
        <kinematic>0</kinematic>
      </link>
    </model>
    <gravity>0 0 -9.8</gravity>
    <magnetic_field>6e-06 2.3e-05 -4.2e-05</magnetic_field>
    <atmosphere type='adiabatic'/>
    <physics name='default_physics' default='0' type='ode'>
      <max_step_size>0.001</max_step_size>
      <real_time_factor>1</real_time_factor>
      <real_time_update_rate>1000</real_time_update_rate>
    </physics>
    <scene>
      <ambient>0.4 0.4 0.4 1</ambient>
      <background>0.7 0.7 0.7 1</background>
      <shadows>1</shadows>
    </scene>
    <spherical_coordinates>
      <surface_model>EARTH_WGS84</surface_model>
      <latitude_deg>0</latitude_deg>
      <longitude_deg>0</longitude_deg>
      <elevation>0</elevation>
      <heading_deg>0</heading_deg>
    </spherical_coordinates>
    <model name='tiago'>
      <link name='base_footprint'>
        <pose frame=''>0 0 0 0 -0 0</pose>
        <inertial>
          <pose frame=''>-0.00978 -0.00152 0.213783 0 -0 0</pose>
          <mass>42.8506</mass>
          <inertia>
            <ixx>2.01958</ixx>
            <ixy>0.00074088</ixy>
            <ixz>0.109957</ixz>
            <iyy>2.0976</iyy>
            <iyz>0.0139293</iyz>
            <izz>0.666852</izz>
          </inertia>
        </inertial>
        <collision name='base_footprint_fixed_joint_lump__base_link_collision'>
          <pose frame=''>0 0 0.0985 0 -0 0</pose>
          <geometry>
            <mesh>
              <scale>1 1 1</scale>
              <uri>/home/mohamed/tiago_public_ws/src/pmb2_robot/pmb2_description/meshes/base/high_resolution/base_collision.stl</uri>
            </mesh>
          </geometry>
          <surface>
            <contact>
              <ode/>
            </contact>
            <friction>
              <ode/>
              <torsional>
                <ode/>
              </torsional>
            </friction>
            <bounce/>
          </surface>
          <max_contacts>10</max_contacts>
        </collision>
        <collision name='base_footprint_fixed_joint_lump__base_antenna_left_link_collision_1'>
          <pose frame=''>-0.201 0.1062 0.3785 0 -0 0</pose>
          <geometry>
            <cylinder>
              <length>0.17</length>
              <radius>0.005</radius>
            </cylinder>
          </geometry>
          <surface>
            <contact>
              <ode/>
            </contact>
            <friction>
              <ode/>
              <torsional>
                <ode/>
              </torsional>
            </friction>
            <bounce/>
          </surface>
          <max_contacts>10</max_contacts>
        </collision>
        <collision name='base_footprint_fixed_joint_lump__base_antenna_right_link_collision_2'>
          <pose frame=''>-0.201 -0.1062 0.3785 0 -0 0</pose>
          <geometry>
            <cylinder>
              <length>0.17</length>
              <radius>0.005</radius>
            </cylinder>
          </geometry>
          <surface>
            <contact>
              <ode/>
            </contact>
            <friction>
              <ode/>
              <torsional>
                <ode/>
              </torsional>
            </friction>
            <bounce/>
          </surface>
          <max_contacts>10</max_contacts>
        </collision>
        <collision name='base_footprint_fixed_joint_lump__torso_fixed_column_link_collision_3'>
          <pose frame=''>-0.062 0 0.5685 0 -0 0</pose>
          <geometry>
            <box>
              <size>0.23 0.23 0.55</size>
            </box>
          </geometry>
          <surface>
            <contact>
              <ode/>
            </contact>
            <friction>
              <ode/>
              <torsional>
                <ode/>
              </torsional>
            </friction>
            <bounce/>
          </surface>
          <max_contacts>10</max_contacts>
        </collision>
        <collision name='base_footprint_fixed_joint_lump__torso_fixed_link_collision_4'>
          <pose frame=''>0.023 0 0.3115 0 -0 0</pose>
          <geometry>
            <box>
              <size>0.4 0.25 0.04</size>
            </box>
          </geometry>
          <max_contacts>10</max_contacts>
          <surface>
            <contact>
              <ode/>
            </contact>
            <bounce/>
            <friction>
              <torsional>
                <ode/>
              </torsional>
              <ode/>
            </friction>
          </surface>
        </collision>
        <collision name='base_footprint_fixed_joint_lump__torso_fixed_link_collision_5'>
          <pose frame=''>-0.062 0 0.3415 0 -0 0</pose>
          <geometry>
            <box>
              <size>0.25 0.25 0.1</size>
            </box>
          </geometry>
          <max_contacts>10</max_contacts>
          <surface>
            <contact>
              <ode/>
            </contact>
            <bounce/>
            <friction>
              <torsional>
                <ode/>
              </torsional>
              <ode/>
            </friction>
          </surface>
        </collision>
        <visual name='base_footprint_fixed_joint_lump__base_link_visual'>
          <pose frame=''>0 0 0.0985 0 -0 0</pose>
          <geometry>
            <mesh>
              <scale>1 1 1</scale>
              <uri>/home/mohamed/tiago_public_ws/src/pmb2_robot/pmb2_description/meshes/base/base.stl</uri>
            </mesh>
          </geometry>
          <material>
            <script>
              <name>Gazebo/White</name>
              <uri>file://media/materials/scripts/gazebo.material</uri>
            </script>
          </material>
        </visual>
        <visual name='base_footprint_fixed_joint_lump__base_antenna_left_link_visual_1'>
          <pose frame=''>-0.201 0.1062 0.2935 0 -0 0</pose>
          <geometry>
            <mesh>
              <scale>1 1 1</scale>
              <uri>/home/mohamed/tiago_public_ws/src/pmb2_robot/pmb2_description/meshes/objects/antenna.stl</uri>
            </mesh>
          </geometry>
          <material>
            <script>
              <name>Gazebo/Black</name>
              <uri>file://media/materials/scripts/gazebo.material</uri>
            </script>
          </material>
        </visual>
        <visual name='base_footprint_fixed_joint_lump__base_antenna_right_link_visual_2'>
          <pose frame=''>-0.201 -0.1062 0.2935 0 -0 0</pose>
          <geometry>
            <mesh>
              <scale>1 1 1</scale>
              <uri>/home/mohamed/tiago_public_ws/src/pmb2_robot/pmb2_description/meshes/objects/antenna.stl</uri>
            </mesh>
          </geometry>
          <material>
            <script>
              <name>Gazebo/Black</name>
              <uri>file://media/materials/scripts/gazebo.material</uri>
            </script>
          </material>
        </visual>
        <visual name='base_footprint_fixed_joint_lump__base_laser_link_visual_3'>
          <pose frame=''>0.202 0 0.0945 0 -0 0</pose>
          <geometry>
            <mesh>
              <scale>1 1 1</scale>
              <uri>/home/mohamed/tiago_public_ws/src/pmb2_robot/pmb2_description/meshes/sensors/sick_tim551.stl</uri>
            </mesh>
          </geometry>
          <material>
            <script>
              <name>Gazebo/DarkGrey</name>
              <uri>file://media/materials/scripts/gazebo.material</uri>
            </script>
          </material>
        </visual>
        <visual name='base_footprint_fixed_joint_lump__base_sonar_01_link_visual_4'>
          <pose frame=''>-0.183 -0.183 0.2715 0 -0 -2.35619</pose>
          <geometry>
            <mesh>
              <scale>1 1 1</scale>
              <uri>/home/mohamed/tiago_public_ws/src/pmb2_robot/pmb2_description/meshes/sensors/srf05.stl</uri>
            </mesh>
          </geometry>
          <material>
            <script>
              <name>Gazebo/DarkGrey</name>
              <uri>file://media/materials/scripts/gazebo.material</uri>
            </script>
          </material>
        </visual>
        <visual name='base_footprint_fixed_joint_lump__base_sonar_02_link_visual_5'>
          <pose frame=''>-0.259 0 0.2715 0 -0 -3.14159</pose>
          <geometry>
            <mesh>
              <scale>1 1 1</scale>
              <uri>/home/mohamed/tiago_public_ws/src/pmb2_robot/pmb2_description/meshes/sensors/srf05.stl</uri>
            </mesh>
          </geometry>
          <material>
            <script>
              <name>Gazebo/DarkGrey</name>
              <uri>file://media/materials/scripts/gazebo.material</uri>
            </script>
          </material>
        </visual>
        <visual name='base_footprint_fixed_joint_lump__base_sonar_03_link_visual_6'>
          <pose frame=''>-0.183 0.183 0.2715 0 -0 2.35619</pose>
          <geometry>
            <mesh>
              <scale>1 1 1</scale>
              <uri>/home/mohamed/tiago_public_ws/src/pmb2_robot/pmb2_description/meshes/sensors/srf05.stl</uri>
            </mesh>
          </geometry>
          <material>
            <script>
              <name>Gazebo/DarkGrey</name>
              <uri>file://media/materials/scripts/gazebo.material</uri>
            </script>
          </material>
        </visual>
        <visual name='base_footprint_fixed_joint_lump__torso_fixed_column_link_visual_7'>
          <pose frame=''>-0.062 0 0.5685 0 -0 0</pose>
          <geometry>
            <box>
              <size>0.18 0.2 0.55</size>
            </box>
          </geometry>
          <material>
            <script>
              <name>Gazebo/DarkGrey</name>
              <uri>file://media/materials/scripts/gazebo.material</uri>
            </script>
          </material>
        </visual>
        <visual name='base_footprint_fixed_joint_lump__torso_fixed_link_visual_8'>
          <pose frame=''>-0.062 0 0.2915 0 -0 0</pose>
          <geometry>
            <mesh>
              <scale>1 1 1</scale>
              <uri>/home/mohamed/tiago_public_ws/src/tiago_robot/tiago_description/meshes/torso/torso_fix.stl</uri>
            </mesh>
          </geometry>
        </visual>
        <visual name='base_footprint_fixed_joint_lump__base_cover_link_visual_9'>
          <pose frame=''>0 0 0.13 0 -0 0</pose>
          <geometry>
            <mesh>
              <scale>1 1 1</scale>
              <uri>/home/mohamed/tiago_public_ws/src/pmb2_robot/pmb2_description/meshes/base/base_ring.stl</uri>
            </mesh>
          </geometry>
          <material>
            <script>
              <name>Gazebo/Orange</name>
              <uri>file://media/materials/scripts/gazebo.material</uri>
            </script>
          </material>
        </visual>
        <velocity_decay/>
        <velocity_decay/>
        <velocity_decay/>
        <velocity_decay/>
        <velocity_decay/>
        <sensor name='imu_sensor' type='imu'>
          <always_on>1</always_on>
          <update_rate>1000</update_rate>
          <imu>
            <angular_velocity>
              <x>
                <noise type='gaussian'>
                  <mean>0</mean>
                  <stddev>0.0002</stddev>
                  <bias_mean>7.5e-06</bias_mean>
                  <bias_stddev>8e-07</bias_stddev>
                </noise>
              </x>
              <y>
                <noise type='gaussian'>
                  <mean>0</mean>
                  <stddev>0.0002</stddev>
                  <bias_mean>7.5e-06</bias_mean>
                  <bias_stddev>8e-07</bias_stddev>
                </noise>
              </y>
              <z>
                <noise type='gaussian'>
                  <mean>0</mean>
                  <stddev>0.0002</stddev>
                  <bias_mean>7.5e-06</bias_mean>
                  <bias_stddev>8e-07</bias_stddev>
                </noise>
              </z>
            </angular_velocity>
            <linear_acceleration>
              <x>
                <noise type='gaussian'>
                  <mean>0</mean>
                  <stddev>0.017</stddev>
                  <bias_mean>0.1</bias_mean>
                  <bias_stddev>0.001</bias_stddev>
                </noise>
              </x>
              <y>
                <noise type='gaussian'>
                  <mean>0</mean>
                  <stddev>0.017</stddev>
                  <bias_mean>0.1</bias_mean>
                  <bias_stddev>0.001</bias_stddev>
                </noise>
              </y>
              <z>
                <noise type='gaussian'>
                  <mean>0</mean>
                  <stddev>0.017</stddev>
                  <bias_mean>0.1</bias_mean>
                  <bias_stddev>0.001</bias_stddev>
                </noise>
              </z>
            </linear_acceleration>
          </imu>
          <pose frame=''>0.10171 0 0.21132 0 0 -1.5708</pose>
        </sensor>
        <velocity_decay/>
        <sensor name='base_imu_sensor' type='imu'>
          <always_on>1</always_on>
          <update_rate>100</update_rate>
          <imu>
            <angular_velocity>
              <x>
                <noise type='gaussian'>
                  <mean>0</mean>
                  <stddev>0.0002</stddev>
                  <bias_mean>7.5e-06</bias_mean>
                  <bias_stddev>8e-07</bias_stddev>
                </noise>
              </x>
              <y>
                <noise type='gaussian'>
                  <mean>0</mean>
                  <stddev>0.0002</stddev>
                  <bias_mean>7.5e-06</bias_mean>
                  <bias_stddev>8e-07</bias_stddev>
                </noise>
              </y>
              <z>
                <noise type='gaussian'>
                  <mean>0</mean>
                  <stddev>0.0002</stddev>
                  <bias_mean>7.5e-06</bias_mean>
                  <bias_stddev>8e-07</bias_stddev>
                </noise>
              </z>
            </angular_velocity>
            <linear_acceleration>
              <x>
                <noise type='gaussian'>
                  <mean>0</mean>
                  <stddev>0.017</stddev>
                  <bias_mean>0.1</bias_mean>
                  <bias_stddev>0.001</bias_stddev>
                </noise>
              </x>
              <y>
                <noise type='gaussian'>
                  <mean>0</mean>
                  <stddev>0.017</stddev>
                  <bias_mean>0.1</bias_mean>
                  <bias_stddev>0.001</bias_stddev>
                </noise>
              </y>
              <z>
                <noise type='gaussian'>
                  <mean>0</mean>
                  <stddev>0.017</stddev>
                  <bias_mean>0.1</bias_mean>
                  <bias_stddev>0.001</bias_stddev>
                </noise>
              </z>
            </linear_acceleration>
          </imu>
          <pose frame=''>0.10171 0 0.21132 0 0 -1.5708</pose>
        </sensor>
        <velocity_decay/>
        <sensor name='base_laser' type='ray'>
          <update_rate>10</update_rate>
          <visualize>1</visualize>
          <ray>
            <scan>
              <horizontal>
                <samples>666</samples>
                <resolution>1</resolution>
                <min_angle>-1.91986</min_angle>
                <max_angle>1.91986</max_angle>
              </horizontal>
              <vertical>
                <samples>1</samples>
                <min_angle>0</min_angle>
                <max_angle>0</max_angle>
              </vertical>
            </scan>
            <range>
              <min>0.05</min>
              <max>25</max>
              <resolution>0.001</resolution>
            </range>
          </ray>
          <plugin name='gazebo_ros_sick_laser' filename='libgazebo_ros_laser.so'>
            <gaussianNoise>0.06</gaussianNoise>
            <alwaysOn>true</alwaysOn>
            <updateRate>10</updateRate>
            <topicName>scan_raw</topicName>
            <frameName>base_laser_link</frameName>
            <robotNamespace>/</robotNamespace>
          </plugin>
          <pose frame=''>0.202 0 0.0945 0 -0 0</pose>
        </sensor>
        <velocity_decay/>
        <sensor name='base_sonar_01' type='ray'>
          <update_rate>5</update_rate>
          <visualize>0</visualize>
          <ray>
            <scan>
              <horizontal>
                <samples>5</samples>
                <resolution>1</resolution>
                <min_angle>-0.25</min_angle>
                <max_angle>0.25</max_angle>
              </horizontal>
              <vertical>
                <samples>5</samples>
                <resolution>1</resolution>
                <min_angle>-0.25</min_angle>
                <max_angle>0.25</max_angle>
              </vertical>
            </scan>
            <range>
              <min>0.02</min>
              <max>1</max>
              <resolution>0.01</resolution>
            </range>
          </ray>
          <plugin name='gazebo_ros_range' filename='libgazebo_ros_range.so'>
            <gaussianNoise>0.005</gaussianNoise>
            <alwaysOn>true</alwaysOn>
            <updateRate>5</updateRate>
            <topicName>sonar_base</topicName>
            <frameName>base_sonar_01_link</frameName>
            <minRange>0.02</minRange>
            <maxRange>1.0</maxRange>
            <fov>0.5</fov>
            <radiation>ultrasound</radiation>
            <robotNamespace>/</robotNamespace>
          </plugin>
          <pose frame=''>-0.183 -0.183 0.2715 0 -0 -2.35619</pose>
        </sensor>
        <velocity_decay/>
        <sensor name='base_sonar_02' type='ray'>
          <update_rate>5</update_rate>
          <visualize>0</visualize>
          <ray>
            <scan>
              <horizontal>
                <samples>5</samples>
                <resolution>1</resolution>
                <min_angle>-0.25</min_angle>
                <max_angle>0.25</max_angle>
              </horizontal>
              <vertical>
                <samples>5</samples>
                <resolution>1</resolution>
                <min_angle>-0.25</min_angle>
                <max_angle>0.25</max_angle>
              </vertical>
            </scan>
            <range>
              <min>0.02</min>
              <max>1</max>
              <resolution>0.01</resolution>
            </range>
          </ray>
          <plugin name='gazebo_ros_range' filename='libgazebo_ros_range.so'>
            <gaussianNoise>0.005</gaussianNoise>
            <alwaysOn>true</alwaysOn>
            <updateRate>5</updateRate>
            <topicName>sonar_base</topicName>
            <frameName>base_sonar_02_link</frameName>
            <minRange>0.02</minRange>
            <maxRange>1.0</maxRange>
            <fov>0.5</fov>
            <radiation>ultrasound</radiation>
            <robotNamespace>/</robotNamespace>
          </plugin>
          <pose frame=''>-0.259 0 0.2715 0 -0 -3.14159</pose>
        </sensor>
        <velocity_decay/>
        <sensor name='base_sonar_03' type='ray'>
          <update_rate>5</update_rate>
          <visualize>0</visualize>
          <ray>
            <scan>
              <horizontal>
                <samples>5</samples>
                <resolution>1</resolution>
                <min_angle>-0.25</min_angle>
                <max_angle>0.25</max_angle>
              </horizontal>
              <vertical>
                <samples>5</samples>
                <resolution>1</resolution>
                <min_angle>-0.25</min_angle>
                <max_angle>0.25</max_angle>
              </vertical>
            </scan>
            <range>
              <min>0.02</min>
              <max>1</max>
              <resolution>0.01</resolution>
            </range>
          </ray>
          <plugin name='gazebo_ros_range' filename='libgazebo_ros_range.so'>
            <gaussianNoise>0.005</gaussianNoise>
            <alwaysOn>true</alwaysOn>
            <updateRate>5</updateRate>
            <topicName>sonar_base</topicName>
            <frameName>base_sonar_03_link</frameName>
            <minRange>0.02</minRange>
            <maxRange>1.0</maxRange>
            <fov>0.5</fov>
            <radiation>ultrasound</radiation>
            <robotNamespace>/</robotNamespace>
          </plugin>
          <pose frame=''>-0.183 0.183 0.2715 0 -0 2.35619</pose>
        </sensor>
        <velocity_decay/>
        <gravity>1</gravity>
        <velocity_decay/>
        <self_collide>0</self_collide>
        <kinematic>0</kinematic>
      </link>
      <link name='caster_back_left_1_link'>
        <pose frame=''>-0.1735 0.102 0.065 0 -0 0</pose>
        <inertial>
          <pose frame=''>-0.006346 5.3e-05 -0.020375 0 -0 0</pose>
          <mass>0.0514476</mass>
          <inertia>
            <ixx>1.513e-05</ixx>
            <ixy>-3e-08</ixy>
            <ixz>2.67e-06</ixz>
            <iyy>1.309e-05</iyy>
            <iyz>-5e-08</iyz>
            <izz>1.198e-05</izz>
          </inertia>
        </inertial>
        <visual name='caster_back_left_1_link_visual'>
          <pose frame=''>0 0 0 0 -0 0</pose>
          <geometry>
            <mesh>
              <scale>1 1 1</scale>
              <uri>/home/mohamed/tiago_public_ws/src/pmb2_robot/pmb2_description/meshes/wheels/caster_1.stl</uri>
            </mesh>
          </geometry>
          <material>
            <script>
              <name>Gazebo/DarkGrey</name>
              <uri>file://media/materials/scripts/gazebo.material</uri>
            </script>
          </material>
        </visual>
        <gravity>1</gravity>
        <velocity_decay/>
        <self_collide>0</self_collide>
        <kinematic>0</kinematic>
      </link>
      <joint name='caster_back_left_1_joint' type='revolute'>
        <child>caster_back_left_1_link</child>
        <parent>base_footprint</parent>
        <axis>
          <xyz>0 0 1</xyz>
          <limit>
            <lower>-1e+16</lower>
            <upper>1e+16</upper>
          </limit>
          <dynamics>
            <damping>0.005</damping>
            <friction>0</friction>
            <spring_reference>0</spring_reference>
            <spring_stiffness>0</spring_stiffness>
          </dynamics>
          <use_parent_model_frame>1</use_parent_model_frame>
        </axis>
      </joint>
      <link name='caster_back_left_2_link'>
        <pose frame=''>-0.1895 0.102 0.025 -1.5708 0 0</pose>
        <inertial>
          <pose frame=''>0 0 0 0 -0 0</pose>
          <mass>0.0885578</mass>
          <inertia>
            <ixx>1.075e-05</ixx>
            <ixy>0</ixy>
            <ixz>0</ixz>
            <iyy>1.541e-05</iyy>
            <iyz>0</iyz>
            <izz>1.075e-05</izz>
          </inertia>
        </inertial>
        <collision name='caster_back_left_2_link_collision'>
          <pose frame=''>0 0 0 0 -0 0</pose>
          <geometry>
            <cylinder>
              <length>0.015</length>
              <radius>0.025</radius>
            </cylinder>
          </geometry>
          <surface>
            <contact>
              <ode>
                <kp>1e+06</kp>
                <kd>1000</kd>
                <max_vel>1</max_vel>
                <min_depth>0</min_depth>
              </ode>
            </contact>
            <friction>
              <ode>
                <mu>0.4</mu>
                <mu2>0.4</mu2>
                <fdir1>1 0 0</fdir1>
              </ode>
              <torsional>
                <ode/>
              </torsional>
            </friction>
            <bounce/>
          </surface>
          <max_contacts>10</max_contacts>
        </collision>
        <visual name='caster_back_left_2_link_visual'>
          <pose frame=''>0 0 0 0 -0 0</pose>
          <geometry>
            <mesh>
              <scale>1 1 1</scale>
              <uri>/home/mohamed/tiago_public_ws/src/pmb2_robot/pmb2_description/meshes/wheels/caster_2.stl</uri>
            </mesh>
          </geometry>
          <material>
            <script>
              <name>Gazebo/DarkGrey</name>
              <uri>file://media/materials/scripts/gazebo.material</uri>
            </script>
          </material>
        </visual>
        <gravity>1</gravity>
        <velocity_decay/>
        <self_collide>0</self_collide>
        <kinematic>0</kinematic>
      </link>
      <joint name='caster_back_left_2_joint' type='revolute'>
        <child>caster_back_left_2_link</child>
        <parent>caster_back_left_1_link</parent>
        <axis>
          <xyz>0 1 0</xyz>
          <limit>
            <lower>-1e+16</lower>
            <upper>1e+16</upper>
          </limit>
          <dynamics>
            <spring_reference>0</spring_reference>
            <spring_stiffness>0</spring_stiffness>
          </dynamics>
          <use_parent_model_frame>1</use_parent_model_frame>
        </axis>
      </joint>
      <link name='caster_back_right_1_link'>
        <pose frame=''>-0.1735 -0.102 0.065 0 -0 0</pose>
        <inertial>
          <pose frame=''>-0.006346 5.3e-05 -0.020375 0 -0 0</pose>
          <mass>0.0514476</mass>
          <inertia>
            <ixx>1.513e-05</ixx>
            <ixy>-3e-08</ixy>
            <ixz>2.67e-06</ixz>
            <iyy>1.309e-05</iyy>
            <iyz>-5e-08</iyz>
            <izz>1.198e-05</izz>
          </inertia>
        </inertial>
        <visual name='caster_back_right_1_link_visual'>
          <pose frame=''>0 0 0 0 -0 0</pose>
          <geometry>
            <mesh>
              <scale>1 1 1</scale>
              <uri>/home/mohamed/tiago_public_ws/src/pmb2_robot/pmb2_description/meshes/wheels/caster_1.stl</uri>
            </mesh>
          </geometry>
          <material>
            <script>
              <name>Gazebo/DarkGrey</name>
              <uri>file://media/materials/scripts/gazebo.material</uri>
            </script>
          </material>
        </visual>
        <gravity>1</gravity>
        <velocity_decay/>
        <self_collide>0</self_collide>
        <kinematic>0</kinematic>
      </link>
      <joint name='caster_back_right_1_joint' type='revolute'>
        <child>caster_back_right_1_link</child>
        <parent>base_footprint</parent>
        <axis>
          <xyz>0 0 1</xyz>
          <limit>
            <lower>-1e+16</lower>
            <upper>1e+16</upper>
          </limit>
          <dynamics>
            <damping>0.005</damping>
            <friction>0</friction>
            <spring_reference>0</spring_reference>
            <spring_stiffness>0</spring_stiffness>
          </dynamics>
          <use_parent_model_frame>1</use_parent_model_frame>
        </axis>
      </joint>
      <link name='caster_back_right_2_link'>
        <pose frame=''>-0.1895 -0.102 0.025 -1.5708 0 0</pose>
        <inertial>
          <pose frame=''>0 0 0 0 -0 0</pose>
          <mass>0.0885578</mass>
          <inertia>
            <ixx>1.075e-05</ixx>
            <ixy>0</ixy>
            <ixz>0</ixz>
            <iyy>1.541e-05</iyy>
            <iyz>0</iyz>
            <izz>1.075e-05</izz>
          </inertia>
        </inertial>
        <collision name='caster_back_right_2_link_collision'>
          <pose frame=''>0 0 0 0 -0 0</pose>
          <geometry>
            <cylinder>
              <length>0.015</length>
              <radius>0.025</radius>
            </cylinder>
          </geometry>
          <surface>
            <contact>
              <ode>
                <kp>1e+06</kp>
                <kd>1000</kd>
                <max_vel>1</max_vel>
                <min_depth>0</min_depth>
              </ode>
            </contact>
            <friction>
              <ode>
                <mu>0.4</mu>
                <mu2>0.4</mu2>
                <fdir1>1 0 0</fdir1>
              </ode>
              <torsional>
                <ode/>
              </torsional>
            </friction>
            <bounce/>
          </surface>
          <max_contacts>10</max_contacts>
        </collision>
        <visual name='caster_back_right_2_link_visual'>
          <pose frame=''>0 0 0 0 -0 0</pose>
          <geometry>
            <mesh>
              <scale>1 1 1</scale>
              <uri>/home/mohamed/tiago_public_ws/src/pmb2_robot/pmb2_description/meshes/wheels/caster_2.stl</uri>
            </mesh>
          </geometry>
          <material>
            <script>
              <name>Gazebo/DarkGrey</name>
              <uri>file://media/materials/scripts/gazebo.material</uri>
            </script>
          </material>
        </visual>
        <gravity>1</gravity>
        <velocity_decay/>
        <self_collide>0</self_collide>
        <kinematic>0</kinematic>
      </link>
      <joint name='caster_back_right_2_joint' type='revolute'>
        <child>caster_back_right_2_link</child>
        <parent>caster_back_right_1_link</parent>
        <axis>
          <xyz>0 1 0</xyz>
          <limit>
            <lower>-1e+16</lower>
            <upper>1e+16</upper>
          </limit>
          <dynamics>
            <spring_reference>0</spring_reference>
            <spring_stiffness>0</spring_stiffness>
          </dynamics>
          <use_parent_model_frame>1</use_parent_model_frame>
        </axis>
      </joint>
      <link name='caster_front_left_1_link'>
        <pose frame=''>0.1695 0.102 0.065 0 -0 0</pose>
        <inertial>
          <pose frame=''>-0.006346 5.3e-05 -0.020375 0 -0 0</pose>
          <mass>0.0514476</mass>
          <inertia>
            <ixx>1.513e-05</ixx>
            <ixy>-3e-08</ixy>
            <ixz>2.67e-06</ixz>
            <iyy>1.309e-05</iyy>
            <iyz>-5e-08</iyz>
            <izz>1.198e-05</izz>
          </inertia>
        </inertial>
        <visual name='caster_front_left_1_link_visual'>
          <pose frame=''>0 0 0 0 -0 0</pose>
          <geometry>
            <mesh>
              <scale>1 1 1</scale>
              <uri>/home/mohamed/tiago_public_ws/src/pmb2_robot/pmb2_description/meshes/wheels/caster_1.stl</uri>
            </mesh>
          </geometry>
          <material>
            <script>
              <name>Gazebo/DarkGrey</name>
              <uri>file://media/materials/scripts/gazebo.material</uri>
            </script>
          </material>
        </visual>
        <gravity>1</gravity>
        <velocity_decay/>
        <self_collide>0</self_collide>
        <kinematic>0</kinematic>
      </link>
      <joint name='caster_front_left_1_joint' type='revolute'>
        <child>caster_front_left_1_link</child>
        <parent>base_footprint</parent>
        <axis>
          <xyz>0 0 1</xyz>
          <limit>
            <lower>-1e+16</lower>
            <upper>1e+16</upper>
          </limit>
          <dynamics>
            <damping>0.005</damping>
            <friction>0</friction>
            <spring_reference>0</spring_reference>
            <spring_stiffness>0</spring_stiffness>
          </dynamics>
          <use_parent_model_frame>1</use_parent_model_frame>
        </axis>
      </joint>
      <link name='caster_front_left_2_link'>
        <pose frame=''>0.1535 0.102 0.025 -1.5708 0 0</pose>
        <inertial>
          <pose frame=''>0 0 0 0 -0 0</pose>
          <mass>0.0885578</mass>
          <inertia>
            <ixx>1.075e-05</ixx>
            <ixy>0</ixy>
            <ixz>0</ixz>
            <iyy>1.541e-05</iyy>
            <iyz>0</iyz>
            <izz>1.075e-05</izz>
          </inertia>
        </inertial>
        <collision name='caster_front_left_2_link_collision'>
          <pose frame=''>0 0 0 0 -0 0</pose>
          <geometry>
            <cylinder>
              <length>0.015</length>
              <radius>0.025</radius>
            </cylinder>
          </geometry>
          <surface>
            <contact>
              <ode>
                <kp>1e+06</kp>
                <kd>1000</kd>
                <max_vel>1</max_vel>
                <min_depth>0</min_depth>
              </ode>
            </contact>
            <friction>
              <ode>
                <mu>0.4</mu>
                <mu2>0.4</mu2>
                <fdir1>1 0 0</fdir1>
              </ode>
              <torsional>
                <ode/>
              </torsional>
            </friction>
            <bounce/>
          </surface>
          <max_contacts>10</max_contacts>
        </collision>
        <visual name='caster_front_left_2_link_visual'>
          <pose frame=''>0 0 0 0 -0 0</pose>
          <geometry>
            <mesh>
              <scale>1 1 1</scale>
              <uri>/home/mohamed/tiago_public_ws/src/pmb2_robot/pmb2_description/meshes/wheels/caster_2.stl</uri>
            </mesh>
          </geometry>
          <material>
            <script>
              <name>Gazebo/DarkGrey</name>
              <uri>file://media/materials/scripts/gazebo.material</uri>
            </script>
          </material>
        </visual>
        <gravity>1</gravity>
        <velocity_decay/>
        <self_collide>0</self_collide>
        <kinematic>0</kinematic>
      </link>
      <joint name='caster_front_left_2_joint' type='revolute'>
        <child>caster_front_left_2_link</child>
        <parent>caster_front_left_1_link</parent>
        <axis>
          <xyz>0 1 0</xyz>
          <limit>
            <lower>-1e+16</lower>
            <upper>1e+16</upper>
          </limit>
          <dynamics>
            <spring_reference>0</spring_reference>
            <spring_stiffness>0</spring_stiffness>
          </dynamics>
          <use_parent_model_frame>1</use_parent_model_frame>
        </axis>
      </joint>
      <link name='caster_front_right_1_link'>
        <pose frame=''>0.1695 -0.102 0.065 0 -0 0</pose>
        <inertial>
          <pose frame=''>-0.006346 5.3e-05 -0.020375 0 -0 0</pose>
          <mass>0.0514476</mass>
          <inertia>
            <ixx>1.513e-05</ixx>
            <ixy>-3e-08</ixy>
            <ixz>2.67e-06</ixz>
            <iyy>1.309e-05</iyy>
            <iyz>-5e-08</iyz>
            <izz>1.198e-05</izz>
          </inertia>
        </inertial>
        <visual name='caster_front_right_1_link_visual'>
          <pose frame=''>0 0 0 0 -0 0</pose>
          <geometry>
            <mesh>
              <scale>1 1 1</scale>
              <uri>/home/mohamed/tiago_public_ws/src/pmb2_robot/pmb2_description/meshes/wheels/caster_1.stl</uri>
            </mesh>
          </geometry>
          <material>
            <script>
              <name>Gazebo/DarkGrey</name>
              <uri>file://media/materials/scripts/gazebo.material</uri>
            </script>
          </material>
        </visual>
        <gravity>1</gravity>
        <velocity_decay/>
        <self_collide>0</self_collide>
        <kinematic>0</kinematic>
      </link>
      <joint name='caster_front_right_1_joint' type='revolute'>
        <child>caster_front_right_1_link</child>
        <parent>base_footprint</parent>
        <axis>
          <xyz>0 0 1</xyz>
          <limit>
            <lower>-1e+16</lower>
            <upper>1e+16</upper>
          </limit>
          <dynamics>
            <damping>0.005</damping>
            <friction>0</friction>
            <spring_reference>0</spring_reference>
            <spring_stiffness>0</spring_stiffness>
          </dynamics>
          <use_parent_model_frame>1</use_parent_model_frame>
        </axis>
      </joint>
      <link name='caster_front_right_2_link'>
        <pose frame=''>0.1535 -0.102 0.025 -1.5708 0 0</pose>
        <inertial>
          <pose frame=''>0 0 0 0 -0 0</pose>
          <mass>0.0885578</mass>
          <inertia>
            <ixx>1.075e-05</ixx>
            <ixy>0</ixy>
            <ixz>0</ixz>
            <iyy>1.541e-05</iyy>
            <iyz>0</iyz>
            <izz>1.075e-05</izz>
          </inertia>
        </inertial>
        <collision name='caster_front_right_2_link_collision'>
          <pose frame=''>0 0 0 0 -0 0</pose>
          <geometry>
            <cylinder>
              <length>0.015</length>
              <radius>0.025</radius>
            </cylinder>
          </geometry>
          <surface>
            <contact>
              <ode>
                <kp>1e+06</kp>
                <kd>1000</kd>
                <max_vel>1</max_vel>
                <min_depth>0</min_depth>
              </ode>
            </contact>
            <friction>
              <ode>
                <mu>0.4</mu>
                <mu2>0.4</mu2>
                <fdir1>1 0 0</fdir1>
              </ode>
              <torsional>
                <ode/>
              </torsional>
            </friction>
            <bounce/>
          </surface>
          <max_contacts>10</max_contacts>
        </collision>
        <visual name='caster_front_right_2_link_visual'>
          <pose frame=''>0 0 0 0 -0 0</pose>
          <geometry>
            <mesh>
              <scale>1 1 1</scale>
              <uri>/home/mohamed/tiago_public_ws/src/pmb2_robot/pmb2_description/meshes/wheels/caster_2.stl</uri>
            </mesh>
          </geometry>
          <material>
            <script>
              <name>Gazebo/DarkGrey</name>
              <uri>file://media/materials/scripts/gazebo.material</uri>
            </script>
          </material>
        </visual>
        <gravity>1</gravity>
        <velocity_decay/>
        <self_collide>0</self_collide>
        <kinematic>0</kinematic>
      </link>
      <joint name='caster_front_right_2_joint' type='revolute'>
        <child>caster_front_right_2_link</child>
        <parent>caster_front_right_1_link</parent>
        <axis>
          <xyz>0 1 0</xyz>
          <limit>
            <lower>-1e+16</lower>
            <upper>1e+16</upper>
          </limit>
          <dynamics>
            <spring_reference>0</spring_reference>
            <spring_stiffness>0</spring_stiffness>
          </dynamics>
          <use_parent_model_frame>1</use_parent_model_frame>
        </axis>
      </joint>
      <link name='suspension_left_link'>
        <pose frame=''>0 0 0.0985 0 -0 0</pose>
        <inertial>
          <pose frame=''>0 0 -0.02 0 -0 0</pose>
          <mass>10</mass>
          <inertia>
            <ixx>1</ixx>
            <ixy>0</ixy>
            <ixz>0</ixz>
            <iyy>1</iyy>
            <iyz>0</iyz>
            <izz>1</izz>
          </inertia>
        </inertial>
        <self_collide>0</self_collide>
        <kinematic>0</kinematic>
      </link>
      <joint name='suspension_left_joint' type='prismatic'>
        <child>suspension_left_link</child>
        <parent>base_footprint</parent>
        <axis>
          <xyz>0 0 1</xyz>
          <limit>
            <lower>-0.005</lower>
            <upper>0.005</upper>
            <effort>100</effort>
            <velocity>1</velocity>
          </limit>
          <dynamics>
            <damping>100</damping>
            <friction>0</friction>
            <spring_reference>0</spring_reference>
            <spring_stiffness>0</spring_stiffness>
          </dynamics>
          <use_parent_model_frame>1</use_parent_model_frame>
        </axis>
      </joint>
      <link name='wheel_left_link'>
        <pose frame=''>0 0.2022 0.0985 -1.5708 0 0</pose>
        <inertial>
          <pose frame=''>0 0 0.00207 0 -0 0</pose>
          <mass>1.82362</mass>
          <inertia>
            <ixx>0.00499743</ixx>
            <ixy>-4.464e-08</ixy>
            <ixz>-2.245e-08</ixz>
            <iyy>0.00499742</iyy>
            <iyz>1.64e-09</iyz>
            <izz>0.0083924</izz>
          </inertia>
        </inertial>
        <collision name='wheel_left_link_collision'>
          <pose frame=''>0 0 0 0 -0 0</pose>
          <geometry>
            <cylinder>
              <length>0.04</length>
              <radius>0.0985</radius>
            </cylinder>
          </geometry>
          <surface>
            <contact>
              <ode>
                <kp>1e+06</kp>
                <kd>1000</kd>
                <max_vel>1</max_vel>
                <min_depth>0</min_depth>
              </ode>
            </contact>
            <friction>
              <ode>
                <mu>1</mu>
                <mu2>1</mu2>
                <fdir1>1 0 0</fdir1>
              </ode>
              <torsional>
                <ode/>
              </torsional>
            </friction>
            <bounce/>
          </surface>
          <max_contacts>10</max_contacts>
        </collision>
        <visual name='wheel_left_link_visual'>
          <pose frame=''>0 0 0 3.14159 -0 0</pose>
          <geometry>
            <mesh>
              <scale>1 1 1</scale>
              <uri>/home/mohamed/tiago_public_ws/src/pmb2_robot/pmb2_description/meshes/wheels/wheel.stl</uri>
            </mesh>
          </geometry>
          <material>
            <script>
              <name>Gazebo/DarkGrey</name>
              <uri>file://media/materials/scripts/gazebo.material</uri>
            </script>
          </material>
        </visual>
        <gravity>1</gravity>
        <velocity_decay/>
        <self_collide>0</self_collide>
        <kinematic>0</kinematic>
      </link>
      <joint name='wheel_left_joint' type='revolute'>
        <child>wheel_left_link</child>
        <parent>suspension_left_link</parent>
        <axis>
          <xyz>0 1 0</xyz>
          <limit>
            <lower>-1e+16</lower>
            <upper>1e+16</upper>
          </limit>
          <dynamics>
            <spring_reference>0</spring_reference>
            <spring_stiffness>0</spring_stiffness>
          </dynamics>
          <use_parent_model_frame>1</use_parent_model_frame>
        </axis>
      </joint>
      <link name='suspension_right_link'>
        <pose frame=''>0 0 0.0985 0 -0 0</pose>
        <inertial>
          <pose frame=''>0 0 -0.02 0 -0 0</pose>
          <mass>10</mass>
          <inertia>
            <ixx>1</ixx>
            <ixy>0</ixy>
            <ixz>0</ixz>
            <iyy>1</iyy>
            <iyz>0</iyz>
            <izz>1</izz>
          </inertia>
        </inertial>
        <self_collide>0</self_collide>
        <kinematic>0</kinematic>
      </link>
      <joint name='suspension_right_joint' type='prismatic'>
        <child>suspension_right_link</child>
        <parent>base_footprint</parent>
        <axis>
          <xyz>0 0 1</xyz>
          <limit>
            <lower>-0.005</lower>
            <upper>0.005</upper>
            <effort>100</effort>
            <velocity>1</velocity>
          </limit>
          <dynamics>
            <damping>100</damping>
            <friction>0</friction>
            <spring_reference>0</spring_reference>
            <spring_stiffness>0</spring_stiffness>
          </dynamics>
          <use_parent_model_frame>1</use_parent_model_frame>
        </axis>
      </joint>
      <link name='wheel_right_link'>
        <pose frame=''>0 -0.2022 0.0985 -1.5708 0 0</pose>
        <inertial>
          <pose frame=''>0 0 -0.00207 0 -0 0</pose>
          <mass>1.82362</mass>
          <inertia>
            <ixx>0.00499743</ixx>
            <ixy>4.464e-08</ixy>
            <ixz>-2.245e-08</ixz>
            <iyy>0.00499742</iyy>
            <iyz>-1.64e-09</iyz>
            <izz>0.0083924</izz>
          </inertia>
        </inertial>
        <collision name='wheel_right_link_collision'>
          <pose frame=''>0 0 0 0 -0 0</pose>
          <geometry>
            <cylinder>
              <length>0.04</length>
              <radius>0.0985</radius>
            </cylinder>
          </geometry>
          <surface>
            <contact>
              <ode>
                <kp>1e+06</kp>
                <kd>1000</kd>
                <max_vel>1</max_vel>
                <min_depth>0</min_depth>
              </ode>
            </contact>
            <friction>
              <ode>
                <mu>1</mu>
                <mu2>1</mu2>
                <fdir1>1 0 0</fdir1>
              </ode>
              <torsional>
                <ode/>
              </torsional>
            </friction>
            <bounce/>
          </surface>
          <max_contacts>10</max_contacts>
        </collision>
        <visual name='wheel_right_link_visual'>
          <pose frame=''>0 0 0 0 -0 0</pose>
          <geometry>
            <mesh>
              <scale>1 1 1</scale>
              <uri>/home/mohamed/tiago_public_ws/src/pmb2_robot/pmb2_description/meshes/wheels/wheel.stl</uri>
            </mesh>
          </geometry>
          <material>
            <script>
              <name>Gazebo/DarkGrey</name>
              <uri>file://media/materials/scripts/gazebo.material</uri>
            </script>
          </material>
        </visual>
        <gravity>1</gravity>
        <velocity_decay/>
        <self_collide>0</self_collide>
        <kinematic>0</kinematic>
      </link>
      <joint name='wheel_right_joint' type='revolute'>
        <child>wheel_right_link</child>
        <parent>suspension_right_link</parent>
        <axis>
          <xyz>0 1 0</xyz>
          <limit>
            <lower>-1e+16</lower>
            <upper>1e+16</upper>
          </limit>
          <dynamics>
            <spring_reference>0</spring_reference>
            <spring_stiffness>0</spring_stiffness>
          </dynamics>
          <use_parent_model_frame>1</use_parent_model_frame>
        </axis>
      </joint>
      <link name='torso_lift_link'>
        <pose frame=''>-0.062 0 0.8885 0 -0 0</pose>
        <inertial>
          <pose frame=''>0.04361 -0.00116 -0.17334 0 -0 0</pose>
          <mass>6.93198</mass>
          <inertia>
            <ixx>0.24487</ixx>
            <ixy>-0.001456</ixy>
            <ixz>-0.009742</ixz>
            <iyy>0.249269</iyy>
            <iyz>0.008281</iyz>
            <izz>0.090395</izz>
          </inertia>
        </inertial>
        <collision name='torso_lift_link_collision'>
          <pose frame=''>0 0 0 0 -0 0</pose>
          <geometry>
            <mesh>
              <scale>1 1 1</scale>
              <uri>/home/mohamed/tiago_public_ws/src/tiago_robot/tiago_description/meshes/torso/torso_lift_collision_core.dae</uri>
            </mesh>
          </geometry>
          <max_contacts>10</max_contacts>
          <surface>
            <contact>
              <ode/>
            </contact>
            <bounce/>
            <friction>
              <torsional>
                <ode/>
              </torsional>
              <ode/>
            </friction>
          </surface>
        </collision>
        <collision name='torso_lift_link_collision_1'>
          <pose frame=''>0 0 0 0 -0 0</pose>
          <geometry>
            <mesh>
              <scale>1 1 1</scale>
              <uri>/home/mohamed/tiago_public_ws/src/tiago_robot/tiago_description/meshes/torso/torso_lift_collision_shoulder.dae</uri>
            </mesh>
          </geometry>
          <max_contacts>10</max_contacts>
          <surface>
            <contact>
              <ode/>
            </contact>
            <bounce/>
            <friction>
              <torsional>
                <ode/>
              </torsional>
              <ode/>
            </friction>
          </surface>
        </collision>
        <collision name='torso_lift_link_collision_2'>
          <pose frame=''>0 0 0 0 -0 0</pose>
          <geometry>
            <mesh>
              <scale>1 1 1</scale>
              <uri>/home/mohamed/tiago_public_ws/src/tiago_robot/tiago_description/meshes/torso/torso_lift_collision_neck.dae</uri>
            </mesh>
          </geometry>
          <max_contacts>10</max_contacts>
          <surface>
            <contact>
              <ode/>
            </contact>
            <bounce/>
            <friction>
              <torsional>
                <ode/>
              </torsional>
              <ode/>
            </friction>
          </surface>
        </collision>
        <visual name='torso_lift_link_visual'>
          <pose frame=''>0 0 0 0 -0 0</pose>
          <geometry>
            <mesh>
              <scale>1 1 1</scale>
              <uri>/home/mohamed/tiago_public_ws/src/tiago_robot/tiago_description/meshes/torso/torso_lift_with_arm.stl</uri>
            </mesh>
          </geometry>
        </visual>
        <self_collide>0</self_collide>
        <kinematic>0</kinematic>
      </link>
      <joint name='torso_lift_joint' type='prismatic'>
        <child>torso_lift_link</child>
        <parent>base_footprint</parent>
        <axis>
          <xyz>0 0 1</xyz>
          <limit>
            <lower>0</lower>
            <upper>0.35</upper>
            <effort>2000</effort>
            <velocity>0.07</velocity>
          </limit>
          <dynamics>
            <damping>1000</damping>
            <friction>0</friction>
            <spring_reference>0</spring_reference>
            <spring_stiffness>0</spring_stiffness>
          </dynamics>
          <use_parent_model_frame>1</use_parent_model_frame>
        </axis>
      </joint>
      <link name='arm_1_link'>
        <pose frame=''>0.09305 0.014 0.7375 0 0 -1.5708</pose>
        <inertial>
          <pose frame=''>0.061191 -0.022397 -0.012835 0 -0 0</pose>
          <mass>1.56343</mass>
          <inertia>
            <ixx>0.002471</ixx>
            <ixy>-0.001809</ixy>
            <ixz>-0.001202</ixz>
            <iyy>0.006132</iyy>
            <iyz>0.000494</iyz>
            <izz>0.006704</izz>
          </inertia>
        </inertial>
        <collision name='arm_1_link_collision'>
          <pose frame=''>0 0 0 0 -0 0</pose>
          <geometry>
            <mesh>
              <scale>1 1 1</scale>
              <uri>/home/mohamed/tiago_public_ws/src/tiago_robot/tiago_description/meshes/arm/arm_1_collision.dae</uri>
            </mesh>
          </geometry>
          <surface>
            <contact>
              <ode/>
            </contact>
            <friction>
              <ode>
                <mu>0.9</mu>
                <mu2>0.9</mu2>
              </ode>
              <torsional>
                <ode/>
              </torsional>
            </friction>
            <bounce/>
          </surface>
          <max_contacts>10</max_contacts>
        </collision>
        <visual name='arm_1_link_visual'>
          <pose frame=''>0 0 0 0 -0 0</pose>
          <geometry>
            <mesh>
              <scale>1 1 1</scale>
              <uri>/home/mohamed/tiago_public_ws/src/tiago_robot/tiago_description/meshes/arm/arm_1.stl</uri>
            </mesh>
          </geometry>
          <material>
            <script>
              <name>Gazebo/DarkGrey</name>
              <uri>file://media/materials/scripts/gazebo.material</uri>
            </script>
          </material>
        </visual>
        <gravity>1</gravity>
        <velocity_decay/>
        <self_collide>0</self_collide>
        <kinematic>0</kinematic>
      </link>
      <joint name='arm_1_joint' type='revolute'>
        <child>arm_1_link</child>
        <parent>torso_lift_link</parent>
        <axis>
          <xyz>0 0 1</xyz>
          <limit>
            <lower>0</lower>
            <upper>2.74889</upper>
            <effort>43</effort>
            <velocity>1.95</velocity>
          </limit>
          <dynamics>
            <damping>1</damping>
            <friction>1</friction>
            <spring_reference>0</spring_reference>
            <spring_stiffness>0</spring_stiffness>
          </dynamics>
          <use_parent_model_frame>1</use_parent_model_frame>
        </axis>
        <physics>
          <ode>
            <implicit_spring_damper>1</implicit_spring_damper>
            <cfm_damping>1</cfm_damping>
            <limit>
              <cfm>0</cfm>
              <erp>0.2</erp>
            </limit>
          </ode>
        </physics>
      </joint>
      <link name='arm_2_link'>
        <pose frame=''>0.11255 -0.111 0.7065 1.5708 0 -1.5708</pose>
        <inertial>
          <pose frame=''>0.030432 0.000229 -0.005942 0 -0 0</pose>
          <mass>1.8004</mass>
          <inertia>
            <ixx>0.001809</ixx>
            <ixy>1.5e-05</ixy>
            <ixz>0.000254</ixz>
            <iyy>0.004333</iyy>
            <iyz>1.4e-05</iyz>
            <izz>0.004341</izz>
          </inertia>
        </inertial>
        <collision name='arm_2_link_collision'>
          <pose frame=''>0 0 0 0 -0 0</pose>
          <geometry>
            <mesh>
              <scale>1 1 1</scale>
              <uri>/home/mohamed/tiago_public_ws/src/tiago_robot/tiago_description/meshes/arm/arm_2_collision.dae</uri>
            </mesh>
          </geometry>
          <surface>
            <contact>
              <ode/>
            </contact>
            <friction>
              <ode>
                <mu>0.9</mu>
                <mu2>0.9</mu2>
              </ode>
              <torsional>
                <ode/>
              </torsional>
            </friction>
            <bounce/>
          </surface>
          <max_contacts>10</max_contacts>
        </collision>
        <visual name='arm_2_link_visual'>
          <pose frame=''>0 0 0 0 -0 0</pose>
          <geometry>
            <mesh>
              <scale>1 1 1</scale>
              <uri>/home/mohamed/tiago_public_ws/src/tiago_robot/tiago_description/meshes/arm/arm_2.stl</uri>
            </mesh>
          </geometry>
          <material>
            <script>
              <name>Gazebo/DarkGrey</name>
              <uri>file://media/materials/scripts/gazebo.material</uri>
            </script>
          </material>
        </visual>
        <gravity>1</gravity>
        <velocity_decay/>
        <self_collide>0</self_collide>
        <kinematic>0</kinematic>
      </link>
      <joint name='arm_2_joint' type='revolute'>
        <child>arm_2_link</child>
        <parent>arm_1_link</parent>
        <axis>
          <xyz>-1 0 0</xyz>
          <limit>
            <lower>-1.5708</lower>
            <upper>1.09083</upper>
            <effort>43</effort>
            <velocity>1.95</velocity>
          </limit>
          <dynamics>
            <damping>1</damping>
            <friction>1</friction>
            <spring_reference>0</spring_reference>
            <spring_stiffness>0</spring_stiffness>
          </dynamics>
          <use_parent_model_frame>1</use_parent_model_frame>
        </axis>
        <physics>
          <ode>
            <implicit_spring_damper>1</implicit_spring_damper>
            <cfm_damping>1</cfm_damping>
            <limit>
              <cfm>0</cfm>
              <erp>0.2</erp>
            </limit>
          </ode>
        </physics>
      </joint>
      <link name='arm_3_link'>
        <pose frame=''>0.11405 -0.2005 0.7065 1.57079 -1.57079 3.14159</pose>
        <inertial>
          <pose frame=''>0.007418 -0.004361 -0.134194 0 -0 0</pose>
          <mass>2.3435</mass>
          <inertia>
            <ixx>0.019541</ixx>
            <ixy>-0.000105</ixy>
            <ixz>-0.001717</ixz>
            <iyy>0.019936</iyy>
            <iyz>0.000852</iyz>
            <izz>0.002864</izz>
          </inertia>
        </inertial>
        <collision name='arm_3_link_collision'>
          <pose frame=''>0 0 0 0 -0 0</pose>
          <geometry>
            <mesh>
              <scale>1 1 1</scale>
              <uri>/home/mohamed/tiago_public_ws/src/tiago_robot/tiago_description/meshes/arm/arm_3_collision.dae</uri>
            </mesh>
          </geometry>
          <surface>
            <contact>
              <ode/>
            </contact>
            <friction>
              <ode>
                <mu>0.9</mu>
                <mu2>0.9</mu2>
              </ode>
              <torsional>
                <ode/>
              </torsional>
            </friction>
            <bounce/>
          </surface>
          <max_contacts>10</max_contacts>
        </collision>
        <visual name='arm_3_link_visual'>
          <pose frame=''>0 0 0 0 -0 0</pose>
          <geometry>
            <mesh>
              <scale>1 1 1</scale>
              <uri>/home/mohamed/tiago_public_ws/src/tiago_robot/tiago_description/meshes/arm/arm_3.stl</uri>
            </mesh>
          </geometry>
          <material>
            <script>
              <name>Gazebo/DarkGrey</name>
              <uri>file://media/materials/scripts/gazebo.material</uri>
            </script>
          </material>
        </visual>
        <gravity>1</gravity>
        <velocity_decay/>
        <self_collide>0</self_collide>
        <kinematic>0</kinematic>
      </link>
      <joint name='arm_3_joint' type='revolute'>
        <child>arm_3_link</child>
        <parent>arm_2_link</parent>
        <axis>
          <xyz>0 1 0</xyz>
          <limit>
            <lower>-3.53429</lower>
            <upper>1.5708</upper>
            <effort>26</effort>
            <velocity>2.35</velocity>
          </limit>
          <dynamics>
            <damping>1</damping>
            <friction>1</friction>
            <spring_reference>0</spring_reference>
            <spring_stiffness>0</spring_stiffness>
          </dynamics>
          <use_parent_model_frame>1</use_parent_model_frame>
        </axis>
        <physics>
          <ode>
            <implicit_spring_damper>1</implicit_spring_damper>
            <cfm_damping>1</cfm_damping>
            <limit>
              <cfm>0</cfm>
              <erp>0.2</erp>
            </limit>
          </ode>
        </physics>
      </joint>
      <link name='arm_4_link'>
        <pose frame=''>0.08705 -0.4225 0.6865 1.5708 -0 1.5708</pose>
        <inertial>
          <pose frame=''>-0.095658 0.014666 0.018133 0 -0 0</pose>
          <mass>1.4327</mass>
          <inertia>
            <ixx>0.00204</ixx>
            <ixy>0.000725</ixy>
            <ixz>-0.00115</ixz>
            <iyy>0.008424</iyy>
            <iyz>-0.000204</iyz>
            <izz>0.008686</izz>
          </inertia>
        </inertial>
        <collision name='arm_4_link_collision'>
          <pose frame=''>0 0 0 0 -0 0</pose>
          <geometry>
            <mesh>
              <scale>1 1 1</scale>
              <uri>/home/mohamed/tiago_public_ws/src/tiago_robot/tiago_description/meshes/arm/arm_4_collision.dae</uri>
            </mesh>
          </geometry>
          <surface>
            <contact>
              <ode/>
            </contact>
            <friction>
              <ode>
                <mu>0.9</mu>
                <mu2>0.9</mu2>
              </ode>
              <torsional>
                <ode/>
              </torsional>
            </friction>
            <bounce/>
          </surface>
          <max_contacts>10</max_contacts>
        </collision>
        <visual name='arm_4_link_visual'>
          <pose frame=''>0 0 0 0 -0 0</pose>
          <geometry>
            <mesh>
              <scale>1 1 1</scale>
              <uri>/home/mohamed/tiago_public_ws/src/tiago_robot/tiago_description/meshes/arm/arm_4.stl</uri>
            </mesh>
          </geometry>
          <material>
            <script>
              <name>Gazebo/DarkGrey</name>
              <uri>file://media/materials/scripts/gazebo.material</uri>
            </script>
          </material>
        </visual>
        <gravity>1</gravity>
        <velocity_decay/>
        <self_collide>0</self_collide>
        <kinematic>0</kinematic>
      </link>
      <joint name='arm_4_joint' type='revolute'>
        <child>arm_4_link</child>
        <parent>arm_3_link</parent>
        <axis>
          <xyz>1 0 0</xyz>
          <limit>
            <lower>-0.392699</lower>
            <upper>2.35619</upper>
            <effort>26</effort>
            <velocity>2.35</velocity>
          </limit>
          <dynamics>
            <damping>1</damping>
            <friction>1</friction>
            <spring_reference>0</spring_reference>
            <spring_stiffness>0</spring_stiffness>
          </dynamics>
          <use_parent_model_frame>1</use_parent_model_frame>
        </axis>
        <physics>
          <ode>
            <implicit_spring_damper>1</implicit_spring_damper>
            <cfm_damping>1</cfm_damping>
            <limit>
              <cfm>0</cfm>
              <erp>0.2</erp>
            </limit>
          </ode>
        </physics>
      </joint>
      <link name='arm_5_link'>
        <pose frame=''>0.11405 -0.5845 0.7065 1.5708 -0 0</pose>
        <inertial>
          <pose frame=''>0.001078 -0.000151 -0.077173 0 -0 0</pose>
          <mass>1.65582</mass>
          <inertia>
            <ixx>0.006138</ixx>
            <ixy>-4e-06</ixy>
            <ixz>0.000156</ixz>
            <iyy>0.00564</iyy>
            <iyz>2.2e-05</iyz>
            <izz>0.001797</izz>
          </inertia>
        </inertial>
        <collision name='arm_5_link_collision'>
          <pose frame=''>0 0 0 0 -0 0</pose>
          <geometry>
            <mesh>
              <scale>1 1 1</scale>
              <uri>/home/mohamed/tiago_public_ws/src/tiago_robot/tiago_description/meshes/arm/arm_5_collision.dae</uri>
            </mesh>
          </geometry>
          <surface>
            <contact>
              <ode/>
            </contact>
            <friction>
              <ode>
                <mu>0.9</mu>
                <mu2>0.9</mu2>
              </ode>
              <torsional>
                <ode/>
              </torsional>
            </friction>
            <bounce/>
          </surface>
          <max_contacts>10</max_contacts>
        </collision>
        <visual name='arm_5_link_visual'>
          <pose frame=''>0 0 0 0 -0 0</pose>
          <geometry>
            <mesh>
              <scale>1 1 1</scale>
              <uri>/home/mohamed/tiago_public_ws/src/tiago_robot/tiago_description/meshes/arm/arm_5.stl</uri>
            </mesh>
          </geometry>
          <material>
            <script>
              <uri>__default__</uri>
              <name>__default__</name>
            </script>
          </material>
        </visual>
        <gravity>1</gravity>
        <velocity_decay/>
        <self_collide>0</self_collide>
        <kinematic>0</kinematic>
      </link>
      <joint name='arm_5_joint' type='revolute'>
        <child>arm_5_link</child>
        <parent>arm_4_link</parent>
        <axis>
          <xyz>0 -1 0</xyz>
          <limit>
            <lower>-2.0944</lower>
            <upper>2.0944</upper>
            <effort>3</effort>
            <velocity>1.95</velocity>
          </limit>
          <dynamics>
            <damping>1</damping>
            <friction>1</friction>
            <spring_reference>0</spring_reference>
            <spring_stiffness>0</spring_stiffness>
          </dynamics>
          <use_parent_model_frame>1</use_parent_model_frame>
        </axis>
        <physics>
          <ode>
            <implicit_spring_damper>1</implicit_spring_damper>
            <cfm_damping>1</cfm_damping>
            <limit>
              <cfm>0</cfm>
              <erp>0.2</erp>
            </limit>
          </ode>
        </physics>
      </joint>
      <link name='arm_6_link'>
        <pose frame=''>0.11405 -0.7345 0.7065 0 0 -1.5708</pose>
        <inertial>
          <pose frame=''>-0.000153 -0.003122 0.000183 0 -0 0</pose>
          <mass>0.370063</mass>
          <inertia>
            <ixx>0.000215</ixx>
            <ixy>0</ixy>
            <ixz>0</ixz>
            <iyy>0.00017</iyy>
            <iyz>2e-06</iyz>
            <izz>0.000174</izz>
          </inertia>
        </inertial>
        <collision name='arm_6_link_collision'>
          <pose frame=''>0 0 0 0 -0 0</pose>
          <geometry>
            <mesh>
              <scale>1 1 1</scale>
              <uri>/home/mohamed/tiago_public_ws/src/tiago_robot/tiago_description/meshes/arm/arm_6_collision.dae</uri>
            </mesh>
          </geometry>
          <surface>
            <contact>
              <ode/>
            </contact>
            <friction>
              <ode>
                <mu>0.9</mu>
                <mu2>0.9</mu2>
              </ode>
              <torsional>
                <ode/>
              </torsional>
            </friction>
            <bounce/>
          </surface>
          <max_contacts>10</max_contacts>
        </collision>
        <visual name='arm_6_link_visual'>
          <pose frame=''>0 0 0 0 -0 0</pose>
          <geometry>
            <mesh>
              <scale>1 1 1</scale>
              <uri>/home/mohamed/tiago_public_ws/src/tiago_robot/tiago_description/meshes/arm/arm_6.stl</uri>
            </mesh>
          </geometry>
          <material>
            <script>
              <uri>__default__</uri>
              <name>__default__</name>
            </script>
          </material>
        </visual>
        <gravity>1</gravity>
        <velocity_decay/>
        <self_collide>0</self_collide>
        <kinematic>0</kinematic>
      </link>
      <joint name='arm_6_joint' type='revolute'>
        <child>arm_6_link</child>
        <parent>arm_5_link</parent>
        <axis>
          <xyz>0 0 1</xyz>
          <limit>
            <lower>-1.5708</lower>
            <upper>1.5708</upper>
            <effort>6.6</effort>
            <velocity>1.76</velocity>
          </limit>
          <dynamics>
            <damping>1</damping>
            <friction>1</friction>
            <spring_reference>0</spring_reference>
            <spring_stiffness>0</spring_stiffness>
          </dynamics>
          <use_parent_model_frame>1</use_parent_model_frame>
        </axis>
        <physics>
          <ode>
            <implicit_spring_damper>1</implicit_spring_damper>
            <cfm_damping>1</cfm_damping>
            <limit>
              <cfm>0</cfm>
              <erp>0.2</erp>
            </limit>
          </ode>
        </physics>
      </joint>
      <link name='arm_7_link'>
        <pose frame=''>0.11405 -0.7345 0.7065 1.5708 -0 0</pose>
        <inertial>
          <pose frame=''>-0.000185 0.000188 0.060282 0 -0 0</pose>
          <mass>0.937112</mass>
          <inertia>
            <ixx>0.00279273</ixx>
            <ixy>4.50152e-05</ixy>
            <ixz>5.21089e-06</ixz>
            <iyy>0.00243273</iyy>
            <iyz>-5.15149e-06</iyz>
            <izz>0.000744038</izz>
          </inertia>
        </inertial>
        <collision name='arm_7_link_fixed_joint_lump__arm_tool_link_collision'>
          <pose frame=''>-0 0 0.047 0 -0 -1.5708</pose>
          <geometry>
            <cylinder>
              <length>0.005</length>
              <radius>0.005</radius>
            </cylinder>
          </geometry>
          <max_contacts>10</max_contacts>
          <surface>
            <contact>
              <ode/>
            </contact>
            <bounce/>
            <friction>
              <torsional>
                <ode/>
              </torsional>
              <ode/>
            </friction>
          </surface>
        </collision>
        <collision name='arm_7_link_fixed_joint_lump__gripper_link_collision_1'>
          <pose frame=''>-0 0 0.056 3.14159 -0 -1.5708</pose>
          <geometry>
            <mesh>
              <scale>1 1 1</scale>
              <uri>/home/mohamed/tiago_public_ws/src/pal_gripper/pal_gripper_description/meshes/gripper_link_collision.stl</uri>
            </mesh>
          </geometry>
          <surface>
            <contact>
              <ode/>
            </contact>
            <friction>
              <ode/>
              <torsional>
                <ode/>
              </torsional>
            </friction>
            <bounce/>
          </surface>
          <max_contacts>10</max_contacts>
        </collision>
        <visual name='arm_7_link_fixed_joint_lump__arm_tool_link_visual'>
          <pose frame=''>-0 0 0.047 0 -0 -1.5708</pose>
          <geometry>
            <cylinder>
              <length>0.005</length>
              <radius>0.005</radius>
            </cylinder>
          </geometry>
        </visual>
        <visual name='arm_7_link_fixed_joint_lump__gripper_link_visual_1'>
          <pose frame=''>-0 0 0.056 3.14159 -0 -1.5708</pose>
          <geometry>
            <mesh>
              <scale>1 1 1</scale>
              <uri>/home/mohamed/tiago_public_ws/src/pal_gripper/pal_gripper_description/meshes/gripper_link.stl</uri>
            </mesh>
          </geometry>
          <material>
            <script>
              <name>Gazebo/White</name>
              <uri>file://media/materials/scripts/gazebo.material</uri>
            </script>
          </material>
        </visual>
        <velocity_decay/>
        <gravity>1</gravity>
        <velocity_decay/>
        <self_collide>0</self_collide>
        <kinematic>0</kinematic>
      </link>
      <joint name='arm_7_joint' type='revolute'>
        <child>arm_7_link</child>
        <parent>arm_6_link</parent>
        <axis>
          <xyz>0 -1 0</xyz>
          <limit>
            <lower>-2.0944</lower>
            <upper>2.0944</upper>
            <effort>6.6</effort>
            <velocity>1.76</velocity>
          </limit>
          <dynamics>
            <damping>1</damping>
            <friction>1</friction>
            <spring_reference>0</spring_reference>
            <spring_stiffness>0</spring_stiffness>
          </dynamics>
          <use_parent_model_frame>1</use_parent_model_frame>
        </axis>
        <physics>
          <provide_feedback>1</provide_feedback>
          <ode>
            <provide_feedback>1</provide_feedback>
            <implicit_spring_damper>1</implicit_spring_damper>
            <cfm_damping>1</cfm_damping>
            <limit>
              <cfm>0</cfm>
              <erp>0.2</erp>
            </limit>
          </ode>
        </physics>
      </joint>
      <link name='gripper_left_finger_link'>
        <pose frame=''>0.11405 -0.7905 0.7065 1.57079 1.57079 3.14159</pose>
        <inertial>
          <pose frame=''>-0.00447 0.010766 -0.121013 0 -0 0</pose>
          <mass>0.10998</mass>
          <inertia>
            <ixx>0.000232</ixx>
            <ixy>-5e-06</ixy>
            <ixz>-3.2e-05</ixz>
            <iyy>0.000224</iyy>
            <iyz>3.6e-05</iyz>
            <izz>2.9e-05</izz>
          </inertia>
        </inertial>
        <collision name='gripper_left_finger_link_collision'>
          <pose frame=''>-0.005 0 -0.165 0 -0 3.1415</pose>
          <geometry>
            <box>
              <size>0.01 0.05 0.11</size>
            </box>
          </geometry>
          <surface>
            <contact>
              <ode>
                <kp>1e+06</kp>
                <kd>1</kd>
                <max_vel>1</max_vel>
                <min_depth>0.1</min_depth>
              </ode>
            </contact>
            <friction>
              <ode>
                <mu>1</mu>
                <mu2>1</mu2>
                <fdir1>0 0 0</fdir1>
              </ode>
              <torsional>
                <ode/>
              </torsional>
            </friction>
            <bounce/>
          </surface>
          <max_contacts>10</max_contacts>
        </collision>
        <visual name='gripper_left_finger_link_visual'>
          <pose frame=''>0 0 0 0 -0 3.1415</pose>
          <geometry>
            <mesh>
              <scale>1 1 1</scale>
              <uri>/home/mohamed/tiago_public_ws/src/pal_gripper/pal_gripper_description/meshes/gripper_finger_link.stl</uri>
            </mesh>
          </geometry>
          <material>
            <script>
              <name>Gazebo/Black</name>
              <uri>file://media/materials/scripts/gazebo.material</uri>
            </script>
          </material>
        </visual>
        <velocity_decay/>
        <gravity>1</gravity>
        <velocity_decay/>
        <self_collide>0</self_collide>
        <kinematic>0</kinematic>
      </link>
      <joint name='gripper_left_finger_joint' type='prismatic'>
        <child>gripper_left_finger_link</child>
        <parent>arm_7_link</parent>
        <axis>
          <xyz>0 -0 1</xyz>
          <limit>
            <lower>0</lower>
            <upper>0.045</upper>
            <effort>16</effort>
            <velocity>0.05</velocity>
          </limit>
          <dynamics>
            <damping>80</damping>
            <friction>0</friction>
            <spring_reference>0</spring_reference>
            <spring_stiffness>0</spring_stiffness>
          </dynamics>
          <use_parent_model_frame>1</use_parent_model_frame>
        </axis>
        <physics>
          <provide_feedback>1</provide_feedback>
          <ode>
            <provide_feedback>1</provide_feedback>
            <implicit_spring_damper>1</implicit_spring_damper>
            <cfm_damping>1</cfm_damping>
            <limit>
              <cfm>0</cfm>
              <erp>0.2</erp>
            </limit>
          </ode>
        </physics>
      </joint>
      <link name='gripper_right_finger_link'>
        <pose frame=''>0.11405 -0.7905 0.7065 1.57079 1.57079 3.14159</pose>
        <inertial>
          <pose frame=''>-0.00447 0.010766 -0.121013 0 -0 0</pose>
          <mass>0.10998</mass>
          <inertia>
            <ixx>0.000232</ixx>
            <ixy>-5e-06</ixy>
            <ixz>-3.2e-05</ixz>
            <iyy>0.000224</iyy>
            <iyz>3.6e-05</iyz>
            <izz>2.9e-05</izz>
          </inertia>
        </inertial>
        <collision name='gripper_right_finger_link_collision'>
          <pose frame=''>0.005 0 -0.165 0 -0 3.1415</pose>
          <geometry>
            <box>
              <size>0.01 0.05 0.11</size>
            </box>
          </geometry>
          <surface>
            <contact>
              <ode>
                <kp>1e+06</kp>
                <kd>1</kd>
                <max_vel>1</max_vel>
                <min_depth>0.1</min_depth>
              </ode>
            </contact>
            <friction>
              <ode>
                <mu>1</mu>
                <mu2>1</mu2>
                <fdir1>0 0 0</fdir1>
              </ode>
              <torsional>
                <ode/>
              </torsional>
            </friction>
            <bounce/>
          </surface>
          <max_contacts>10</max_contacts>
        </collision>
        <visual name='gripper_right_finger_link_visual'>
          <pose frame=''>0 0 0 0 -0 3.1415</pose>
          <geometry>
            <mesh>
              <scale>-1 -1 1</scale>
              <uri>/home/mohamed/tiago_public_ws/src/pal_gripper/pal_gripper_description/meshes/gripper_finger_link.stl</uri>
            </mesh>
          </geometry>
          <material>
            <script>
              <name>Gazebo/Black</name>
              <uri>file://media/materials/scripts/gazebo.material</uri>
            </script>
          </material>
        </visual>
        <velocity_decay/>
        <gravity>1</gravity>
        <velocity_decay/>
        <self_collide>0</self_collide>
        <kinematic>0</kinematic>
      </link>
      <joint name='gripper_right_finger_joint' type='prismatic'>
        <child>gripper_right_finger_link</child>
        <parent>arm_7_link</parent>
        <axis>
          <xyz>-0 0 -1</xyz>
          <limit>
            <lower>0</lower>
            <upper>0.045</upper>
            <effort>16</effort>
            <velocity>0.05</velocity>
          </limit>
          <dynamics>
            <damping>80</damping>
            <friction>0</friction>
            <spring_reference>0</spring_reference>
            <spring_stiffness>0</spring_stiffness>
          </dynamics>
          <use_parent_model_frame>1</use_parent_model_frame>
        </axis>
        <physics>
          <provide_feedback>1</provide_feedback>
          <ode>
            <provide_feedback>1</provide_feedback>
            <implicit_spring_damper>1</implicit_spring_damper>
            <cfm_damping>1</cfm_damping>
            <limit>
              <cfm>0</cfm>
              <erp>0.2</erp>
            </limit>
          </ode>
        </physics>
      </joint>
      <link name='head_1_link'>
        <pose frame=''>0.12 0 0.8885 0 -0 0</pose>
        <inertial>
          <pose frame=''>-0.00508 0.00237 0.07229 0 -0 0</pose>
          <mass>0.6222</mass>
          <inertia>
            <ixx>0.001192</ixx>
            <ixy>-7e-06</ixy>
            <ixz>9.6e-05</ixz>
            <iyy>0.001402</iyy>
            <iyz>4e-06</iyz>
            <izz>0.000889</izz>
          </inertia>
        </inertial>
        <collision name='head_1_link_collision'>
          <pose frame=''>0 0 0 0 -0 0</pose>
          <geometry>
            <mesh>
              <scale>1 1 1</scale>
              <uri>/home/mohamed/tiago_public_ws/src/tiago_robot/tiago_description/meshes/head/head_1_collision.dae</uri>
            </mesh>
          </geometry>
          <surface>
            <contact>
              <ode/>
            </contact>
            <friction>
              <ode>
                <mu>0.9</mu>
                <mu2>0.9</mu2>
              </ode>
              <torsional>
                <ode/>
              </torsional>
            </friction>
            <bounce/>
          </surface>
          <max_contacts>10</max_contacts>
        </collision>
        <visual name='head_1_link_visual'>
          <pose frame=''>0 0 0 0 -0 0</pose>
          <geometry>
            <mesh>
              <scale>1 1 1</scale>
              <uri>/home/mohamed/tiago_public_ws/src/tiago_robot/tiago_description/meshes/head/head_1.stl</uri>
            </mesh>
          </geometry>
          <material>
            <script>
              <uri>__default__</uri>
              <name>__default__</name>
            </script>
          </material>
        </visual>
        <gravity>1</gravity>
        <velocity_decay/>
        <self_collide>0</self_collide>
        <kinematic>0</kinematic>
      </link>
      <joint name='head_1_joint' type='revolute'>
        <child>head_1_link</child>
        <parent>torso_lift_link</parent>
        <axis>
          <xyz>0 0 1</xyz>
          <limit>
            <lower>-1.309</lower>
            <upper>1.309</upper>
            <effort>5.197</effort>
            <velocity>3</velocity>
          </limit>
          <dynamics>
            <damping>0.5</damping>
            <friction>1</friction>
            <spring_reference>0</spring_reference>
            <spring_stiffness>0</spring_stiffness>
          </dynamics>
          <use_parent_model_frame>1</use_parent_model_frame>
        </axis>
        <physics>
          <ode>
            <implicit_spring_damper>1</implicit_spring_damper>
            <cfm_damping>1</cfm_damping>
            <limit>
              <cfm>0</cfm>
              <erp>0.2</erp>
            </limit>
          </ode>
        </physics>
      </joint>
      <link name='head_2_link'>
        <pose frame=''>0.125 0 0.9865 1.5708 -0 0</pose>
        <inertial>
          <pose frame=''>0.055788 0.060977 1.6e-05 0 -0 0</pose>
          <mass>0.88593</mass>
          <inertia>
            <ixx>0.00476026</ixx>
            <ixy>0.000561581</ixy>
            <ixz>1.1941e-05</ixz>
            <iyy>0.00512245</iyy>
            <iyz>9.32617e-06</iyz>
            <izz>0.00346439</izz>
          </inertia>
        </inertial>
        <collision name='head_2_link_collision'>
          <pose frame=''>0 0 0 0 -0 0</pose>
          <geometry>
            <mesh>
              <scale>1 1 1</scale>
              <uri>/home/mohamed/tiago_public_ws/src/tiago_robot/tiago_description/meshes/head/head_2_collision.dae</uri>
            </mesh>
          </geometry>
          <max_contacts>10</max_contacts>
          <surface>
            <contact>
              <ode/>
            </contact>
            <bounce/>
            <friction>
              <torsional>
                <ode/>
              </torsional>
              <ode/>
            </friction>
          </surface>
        </collision>
        <visual name='head_2_link_visual'>
          <pose frame=''>0 0 0 0 -0 0</pose>
          <geometry>
            <mesh>
              <scale>1 1 1</scale>
              <uri>/home/mohamed/tiago_public_ws/src/tiago_robot/tiago_description/meshes/head/head_2.stl</uri>
            </mesh>
          </geometry>
        </visual>
        <gravity>1</gravity>
        <velocity_decay/>
        <sensor name='xtion_frame_sensor' type='depth'>
          <always_on>1</always_on>
          <update_rate>30</update_rate>
          <camera name='__default__'>
            <horizontal_fov>1.09956</horizontal_fov>
            <image>
              <format>B8G8R8</format>
              <width>640</width>
              <height>480</height>
            </image>
            <clip>
              <near>0.3</near>
              <far>8</far>
            </clip>
          </camera>
          <plugin name='xtion_frame_controller' filename='libgazebo_ros_openni_kinect.so'>
            <alwaysOn>true</alwaysOn>
            <updateRate>30.0</updateRate>
            <cameraName>xtion</cameraName>
            <imageTopicName>rgb/image_raw</imageTopicName>
            <cameraInfoTopicName>rgb/camera_info</cameraInfoTopicName>
            <depthImageTopicName>depth_registered/image_raw</depthImageTopicName>
            <depthImageCameraInfoTopicName>depth_registered/camera_info</depthImageCameraInfoTopicName>
            <pointCloudTopicName>depth_registered/points</pointCloudTopicName>
            <frameName>xtion_rgb_optical_frame</frameName>
            <pointCloudCutoff>0.5</pointCloudCutoff>
            <pointCloudCutoffMax>8.0</pointCloudCutoffMax>
            <distortionK1>0.00000001</distortionK1>
            <distortionK2>0.00000001</distortionK2>
            <distortionK3>0.00000001</distortionK3>
            <distortionT1>0.00000001</distortionT1>
            <distortionT2>0.00000001</distortionT2>
            <robotNamespace>/</robotNamespace>
          </plugin>
          <pose frame=''>0.0908 0.08 -0.022 -1.5708 0 0</pose>
        </sensor>
        <self_collide>0</self_collide>
        <kinematic>0</kinematic>
      </link>
      <joint name='head_2_joint' type='revolute'>
        <child>head_2_link</child>
        <parent>head_1_link</parent>
        <axis>
          <xyz>0 -1 0</xyz>
          <limit>
            <lower>-1.0472</lower>
            <upper>0.785398</upper>
            <effort>2.77</effort>
            <velocity>3</velocity>
          </limit>
          <dynamics>
            <damping>0.5</damping>
            <friction>1</friction>
            <spring_reference>0</spring_reference>
            <spring_stiffness>0</spring_stiffness>
          </dynamics>
          <use_parent_model_frame>1</use_parent_model_frame>
        </axis>
      </joint>
      <plugin name='gazebo_ros_control' filename='libgazebo_ros_control.so'>
        <ns/>
        <robotSimType>pal_hardware_gazebo/PalHardwareGazebo</robotSimType>
        <robotNamespace/>
        <controlPeriod>0.001</controlPeriod>
      </plugin>
      <plugin name='gazebo_ros_p3d' filename='libgazebo_ros_p3d.so'>
        <bodyName>base_footprint</bodyName>
        <topicName>ground_truth_odom</topicName>
        <alwaysOn>true</alwaysOn>
        <updateRate>100.0</updateRate>
        <robotNamespace>/</robotNamespace>
      </plugin>
      <static>0</static>
      <plugin name='gazebo_ros_odometry' filename='libgazebo_world_odometry.so'>
        <frameName>base_footprint</frameName>
        <topicName>floating_base_pose_simulated</topicName>
        <robotNamespace>/</robotNamespace>
      </plugin>
      <pose frame=''>0 0 0 0 -0 0</pose>
    </model>
    <model name='aruco_marker_original_582'>
      <static>0</static>
      <link name='marker'>
        <inertial>
          <mass>0.1</mass>
          <inertia>
            <ixx>0</ixx>
            <ixy>0</ixy>
            <ixz>0</ixz>
            <iyy>0</iyy>
            <iyz>0</iyz>
            <izz>0</izz>
          </inertia>
        </inertial>
        <visual name='visual'>
          <pose frame=''>0 0 0 0 -0 1.57</pose>
          <geometry>
            <box>
              <size>0.16 0.16 0.001</size>
            </box>
          </geometry>
          <material>
            <script>
              <uri>model://aruco_marker_original_582/material/scripts</uri>
              <uri>model://aruco_marker_original_582/material/textures</uri>
              <name>Aruco/aruco_marker_original_582</name>
            </script>
          </material>
        </visual>
        <collision name='collision'>
          <geometry>
            <box>
              <size>0.16 0.16 0.001</size>
            </box>
          </geometry>
          <surface>
            <bounce/>
            <friction>
              <ode/>
              <torsional>
                <ode/>
              </torsional>
            </friction>
            <contact>
              <ode/>
            </contact>
          </surface>
          <max_contacts>10</max_contacts>
        </collision>
        <self_collide>1</self_collide>
        <kinematic>0</kinematic>
        <gravity>1</gravity>
      </link>
      <pose frame=''>1.54462 0.047427 0 0 -0 0</pose>
    </model>
    <state world_name='default'>
      <sim_time>1789 886000000</sim_time>
      <real_time>207 947223099</real_time>
      <wall_time>1578649250 655083926</wall_time>
      <iterations>100856</iterations>
      <model name='aruco_marker_original_26'>
        <pose frame=''>4.00039 -0.007195 0.0005 2e-06 1e-06 0</pose>
        <scale>1 1 1</scale>
        <link name='marker'>
          <pose frame=''>4.00039 -0.007195 0.0005 2e-06 1e-06 0</pose>
          <velocity>0 0 0 0 -0 0</velocity>
          <acceleration>0 0 0 0 -0 0</acceleration>
          <wrench>-4e-06 4e-06 -0.001253 0 -0 0</wrench>
        </link>
      </model>
      <model name='aruco_marker_original_26_clone'>
        <pose frame=''>4.03371 -1.07563 0.8155 -2e-06 2e-06 -1.57885</pose>
        <scale>1 1 1</scale>
        <link name='marker'>
          <pose frame=''>4.03371 -1.07563 0.8155 -2e-06 2e-06 -1.57885</pose>
          <velocity>0 0 0 0 -0 0</velocity>
          <acceleration>0 0 0 0 -0 0</acceleration>
          <wrench>-4e-06 4e-06 -0.001253 0 -0 0</wrench>
        </link>
      </model>
      <model name='aruco_marker_original_582'>
        <pose frame=''>2.00752 0.003675 0.0005 2e-06 -0 -0.016304</pose>
        <scale>1 1 1</scale>
        <link name='marker'>
          <pose frame=''>2.00752 0.003675 0.0005 2e-06 -0 -0.016304</pose>
          <velocity>0 0 0 0 -0 0</velocity>
          <acceleration>0 0 0 0 -0 0</acceleration>
          <wrench>4e-06 4e-06 0.00308 0 -0 0</wrench>
        </link>
      </model>
      <model name='aruco_marker_original_582_clone'>
        <pose frame=''>2.01637 -1.09892 0.815501 -1e-06 1e-05 -1.57997</pose>
        <scale>1 1 1</scale>
        <link name='marker'>
          <pose frame=''>2.01637 -1.09892 0.815501 -1e-06 1e-05 -1.57997</pose>
          <velocity>0 0 0 0 -0 0</velocity>
          <acceleration>0 0 0 0 -0 0</acceleration>
          <wrench>-4e-06 4e-06 0.017152 0 -0 0</wrench>
        </link>
      </model>
      <model name='aruco_marker_original_63'>
        <pose frame=''>6.01667 -0.017236 0.000501 -6e-06 4e-06 0</pose>
        <scale>1 1 1</scale>
        <link name='marker'>
          <pose frame=''>6.01667 -0.017236 0.000501 -6e-06 4e-06 0</pose>
          <velocity>0 0 0 0 -0 0</velocity>
          <acceleration>0 0 0 0 -0 0</acceleration>
          <wrench>-4e-06 -4e-06 -0.001253 0 -0 0</wrench>
        </link>
      </model>
      <model name='aruco_marker_original_63_clone'>
        <pose frame=''>5.97546 -1.06234 0.8155 -2e-06 -0 -1.52976</pose>
        <scale>1 1 1</scale>
        <link name='marker'>
          <pose frame=''>5.97546 -1.06234 0.8155 -2e-06 -0 -1.52976</pose>
          <velocity>0 0 0 0 -0 0</velocity>
          <acceleration>0 0 0 0 -0 0</acceleration>
          <wrench>-4e-06 -4e-06 -0.001253 0 -0 0</wrench>
        </link>
      </model>
      <model name='ground_plane'>
        <pose frame=''>0 0 0 0 -0 0</pose>
        <scale>1 1 1</scale>
        <link name='link'>
          <pose frame=''>0 0 0 0 -0 0</pose>
          <velocity>0 0 0 0 -0 0</velocity>
          <acceleration>0 0 0 0 -0 0</acceleration>
          <wrench>0 0 0 0 -0 0</wrench>
        </link>
      </model>
      <model name='table'>
        <pose frame=''>2.00371 -1.41381 0 0 -0 0</pose>
        <scale>1 1 1</scale>
        <link name='link'>
          <pose frame=''>2.00371 -1.41381 0 0 -0 0</pose>
          <velocity>0 0 0 0 -0 0</velocity>
          <acceleration>0 0 0 0 -0 0</acceleration>
          <wrench>0 0 0 0 -0 0</wrench>
        </link>
      </model>
      <model name='table_0'>
        <pose frame=''>4.01267 -1.38642 0 0 -0 0</pose>
        <scale>1 1 1</scale>
        <link name='link'>
          <pose frame=''>4.01267 -1.38642 0 0 -0 0</pose>
          <velocity>0 0 0 0 -0 0</velocity>
          <acceleration>0 0 0 0 -0 0</acceleration>
          <wrench>0 0 0 0 -0 0</wrench>
        </link>
      </model>
      <model name='table_1'>
        <pose frame=''>5.96985 -1.37487 0 0 -0 0</pose>
        <scale>1 1 1</scale>
        <link name='link'>
          <pose frame=''>5.96985 -1.37487 0 0 -0 0</pose>
          <velocity>0 0 0 0 -0 0</velocity>
          <acceleration>0 0 0 0 -0 0</acceleration>
          <wrench>0 0 0 0 -0 0</wrench>
        </link>
      </model>
      <model name='tiago'>
        <pose frame=''>0.013974 -0.009481 -0.000274 0.000219 0.00037 -0.032472</pose>
        <scale>1 1 1</scale>
        <link name='arm_1_link'>
          <pose frame=''>0.107752 0.001285 0.88699 -0.000419 0.00025 -1.40327</pose>
          <velocity>2.5e-05 1e-06 0 -8e-06 -0 2.7e-05</velocity>
          <acceleration>-0.00091 0.000384 -0.000153 -1.22158 0.600017 -0.271909</acceleration>
          <wrench>-0.001423 0.0006 -0.00024 0 -0 0</wrench>
        </link>
        <link name='arm_2_link'>
          <pose frame=''>0.147811 -0.118705 0.855953 1.56893 1.33908 -1.40509</pose>
          <velocity>2.8e-05 2e-06 1e-06 -9e-06 -0 2.6e-05</velocity>
          <acceleration>-0.001833 -0.000753 -0.000145 -2.79939 0.361826 2.83879</acceleration>
          <wrench>-0.0033 -0.001355 -0.000261 0 -0 0</wrench>
        </link>
        <link name='arm_3_link'>
          <pose frame=''>0.152682 -0.138727 0.768844 0.046394 -0.227101 -1.60842</pose>
          <velocity>2.9e-05 1e-06 1e-06 -9e-06 -1e-06 2.5e-05</velocity>
          <acceleration>-0.000286 -3.9e-05 -0.000343 0.850853 0.244538 1.26651</acceleration>
          <wrench>-0.00067 -9.1e-05 -0.000804 0 -0 0</wrench>
        </link>
        <link name='arm_4_link'>
          <pose frame=''>0.134865 -0.168804 0.547054 -1.52514 0.139298 -1.59163</pose>
          <velocity>3e-05 -1e-06 1e-06 -5e-06 -1e-06 2.5e-05</velocity>
          <acceleration>0.000718 0.000292 -0.000253 0.187239 0.523582 -3.10136</acceleration>
          <wrench>0.001029 0.000418 -0.000362 0 -0 0</wrench>
        </link>
        <link name='arm_5_link'>
          <pose frame=''>0.166138 -0.006386 0.550982 0.309916 -1.42448 -1.90467</pose>
          <velocity>2.6e-05 0 0 -6e-06 -1.8e-05 2.2e-05</velocity>
          <acceleration>0.000863 0.00027 -0.000131 0.776726 -0.181101 -2.75033</acceleration>
          <wrench>0.001429 0.000447 -0.000217 0 -0 0</wrench>
        </link>
        <link name='arm_6_link'>
          <pose frame=''>0.169231 0.142129 0.571809 0.944586 -1.49489 2.16857</pose>
          <velocity>2.2e-05 0 0 -1.8e-05 -7e-06 2e-05</velocity>
          <acceleration>0.000738 0.000279 -7.4e-05 2.53011 -0.940274 -1.18033</acceleration>
          <wrench>0.000273 0.000103 -2.8e-05 0 -0 0</wrench>
        </link>
        <link name='arm_7_link'>
          <pose frame=''>0.169231 0.142129 0.571809 0.044553 -0.06148 -1.60061</pose>
          <velocity>2.2e-05 0 0 3.9e-05 -9.3e-05 -0.001311</velocity>
          <acceleration>0.001387 -0.0006 -3.7e-05 -0.079621 0.057555 0.627164</acceleration>
          <wrench>0.0013 -0.000563 -3.5e-05 0 -0 0</wrench>
        </link>
        <link name='base_footprint'>
          <pose frame=''>0.013974 -0.009481 -0.000274 0.000219 0.00037 -0.032472</pose>
          <velocity>3.2e-05 -1e-06 4.1e-05 -4e-06 -8e-06 -7e-06</velocity>
          <acceleration>1.3e-05 -3e-06 -1.6e-05 -0.000679 0.000143 0.001998</acceleration>
          <wrench>0.000539 -0.000122 -0.000695 0 -0 0</wrench>
        </link>
        <link name='caster_back_left_1_link'>
          <pose frame=''>-0.156107 0.098082 0.064898 0.000408 0.00267 0.021195</pose>
          <velocity>3.9e-05 -4e-06 0.000128 -0.000199 0.002255 -0.001636</velocity>
          <acceleration>-2.9e-05 -1.8e-05 1e-05 -0.000306 0.003043 -0.001766</acceleration>
          <wrench>-2e-06 -1e-06 1e-06 0 -0 0</wrench>
        </link>
        <link name='caster_back_left_2_link'>
          <pose frame=''>-0.172142 0.097752 0.024962 1.56782 -1.38617 -3.11747</pose>
          <velocity>2.5e-05 1.1e-05 0.00017 0.000541 -0.036597 -0.001406</velocity>
          <acceleration>-3e-05 -8e-06 1.3e-05 0.00035 -0.005688 -0.001122</acceleration>
          <wrench>-3e-06 -1e-06 1e-06 0 -0 0</wrench>
        </link>
        <link name='caster_back_right_1_link'>
          <pose frame=''>-0.162724 -0.105812 0.064877 0.000319 0.003111 0.268193</pose>
          <velocity>3.2e-05 -2e-06 0.000175 -0.001355 0.003289 -0.002734</velocity>
          <acceleration>-1.4e-05 -2.1e-05 1.5e-05 -0.008487 0.055602 -0.004487</acceleration>
          <wrench>-1e-06 -1e-06 1e-06 0 -0 0</wrench>
        </link>
        <link name='caster_back_right_2_link'>
          <pose frame=''>-0.178186 -0.110052 0.024941 -1.57047 -0.589532 0.268034</pose>
          <velocity>-5e-06 2.4e-05 0.000253 -0.002746 0.006234 -0.002261</velocity>
          <acceleration>-2.2e-05 -2.1e-05 1.4e-05 0.000699 -0.000825 0.000124</acceleration>
          <wrench>-2e-06 -2e-06 1e-06 0 -0 0</wrench>
        </link>
        <link name='caster_front_left_1_link'>
          <pose frame=''>0.186708 0.086946 0.064833 0.000483 0.004359 -0.054065</pose>
          <velocity>4.2e-05 -9e-06 0.000205 3e-05 0.004209 -0.002111</velocity>
          <acceleration>-5e-05 -2e-06 -2e-05 -0.001216 -0.007619 -0.002021</acceleration>
          <wrench>-3e-06 0 -1e-06 0 -0 0</wrench>
        </link>
        <link name='caster_front_left_2_link'>
          <pose frame=''>0.170678 0.087824 0.024934 1.56764 -1.35277 3.09061</pose>
          <velocity>1.5e-05 1.3e-05 0.000289 -0.003148 -0.052825 -0.001741</velocity>
          <acceleration>-4.5e-05 0 -2e-06 2.6e-05 -0.002007 -0.0005</acceleration>
          <wrench>-4e-06 0 0 0 -0 0</wrench>
        </link>
        <link name='caster_front_right_1_link'>
          <pose frame=''>0.180083 -0.116944 0.064811 0.000507 0.004953 -0.195225</pose>
          <velocity>4e-05 -1.1e-05 0.000232 0.000752 0.004835 -0.001945</velocity>
          <acceleration>-2.4e-05 0 -2.4e-05 -0.004657 -0.028286 -0.002932</acceleration>
          <wrench>-1e-06 0 -1e-06 0 -0 0</wrench>
        </link>
        <link name='caster_front_right_2_link'>
          <pose frame=''>0.164331 -0.113819 0.024925 1.56755 -1.34476 2.94953</pose>
          <velocity>1.2e-05 1.3e-05 0.000331 -0.011669 -0.057333 -0.001531</velocity>
          <acceleration>-2.6e-05 0 -1.5e-05 0.000516 0.002258 -0.000383</acceleration>
          <wrench>-2e-06 0 -1e-06 0 -0 0</wrench>
        </link>
        <link name='gripper_left_finger_link'>
          <pose frame=''>0.211756 0.144423 0.629647 -3.08006 0.044465 3.11451</pose>
          <velocity>1.7e-05 -5.8e-05 4e-06 3.9e-05 -9.5e-05 -0.001314</velocity>
          <acceleration>0.002928 0.019649 -0.001679 -0.247983 -0.006206 1.31254</acceleration>
          <wrench>0.000322 0.002161 -0.000185 0 -0 0</wrench>
        </link>
        <link name='gripper_right_finger_link'>
          <pose frame=''>0.121902 0.146856 0.625648 -3.08006 0.044465 3.11451</pose>
          <velocity>5e-05 5.9e-05 -3e-06 3.9e-05 -7.9e-05 -0.001298</velocity>
          <acceleration>-0.009667 -0.020427 0.001486 0.068947 0.440186 1.41998</acceleration>
          <wrench>-0.001063 -0.002247 0.000163 0 -0 0</wrench>
        </link>
        <link name='head_1_link'>
          <pose frame=''>0.134288 -0.013617 1.03798 0.000219 0.00037 -0.032382</pose>
          <velocity>2.5e-05 1e-06 0 -4e-06 -1.1e-05 -9e-06</velocity>
          <acceleration>0.000518 6.8e-05 0.000333 -1.28359 -0.080033 0.856506</acceleration>
          <wrench>0.000322 4.2e-05 0.000207 0 -0 0</wrench>
        </link>
        <link name='head_2_link'>
          <pose frame=''>0.139321 -0.013802 1.13597 1.57107 0.59981 -0.032232</pose>
          <velocity>2.4e-05 2e-06 0 -2e-06 1.6e-05 -9e-06</velocity>
          <acceleration>0.000577 2.6e-05 8.4e-05 -1.09383 1.17718 -2.57936</acceleration>
          <wrench>0.000512 2.3e-05 7.5e-05 0 -0 0</wrench>
        </link>
        <link name='suspension_left_link'>
          <pose frame=''>0.01401 -0.009504 0.098398 0.000219 0.000371 -0.032472</pose>
          <velocity>3.1e-05 -1e-06 6.4e-05 -4e-06 -8e-06 -7e-06</velocity>
          <acceleration>-1.2e-05 -1.6e-05 -7e-06 -0.000102 0.000178 6.4e-05</acceleration>
          <wrench>-0.000115 -0.000156 -7.4e-05 0 -0 0</wrench>
        </link>
        <link name='suspension_right_link'>
          <pose frame=''>0.01401 -0.009504 0.098487 0.000219 0.000371 -0.032472</pose>
          <velocity>3.1e-05 -1e-06 7.1e-05 -4e-06 -8e-06 -7e-06</velocity>
          <acceleration>-1.1e-05 -1.6e-05 -4e-06 -0.000102 0.000178 6.4e-05</acceleration>
          <wrench>-0.000113 -0.000157 -3.9e-05 0 -0 0</wrench>
        </link>
        <link name='torso_lift_link'>
          <pose frame=''>-0.047616 -0.007708 1.03804 0.000219 0.000371 -0.032472</pose>
          <velocity>2.3e-05 3e-06 -1e-06 -3e-06 -8e-06 -7e-06</velocity>
          <acceleration>0.000139 6.2e-05 0.000336 -0.002252 -0.000246 -0.012965</acceleration>
          <wrench>0.000961 0.000432 0.002328 0 -0 0</wrench>
        </link>
        <link name='wheel_left_link'>
          <pose frame=''>0.020574 0.192589 0.098442 -1.57038 1.04448 -0.032106</pose>
          <velocity>3.2e-05 -1e-06 6.3e-05 -2.5e-05 -0.000778 -5e-06</velocity>
          <acceleration>-2.1e-05 -7e-06 -2.9e-05 0.036282 1.11422 -9.6e-05</acceleration>
          <wrench>-3.9e-05 -1.2e-05 -5.3e-05 0 -0 0</wrench>
        </link>
        <link name='wheel_right_link'>
          <pose frame=''>0.007445 -0.211597 0.098442 -1.57053 -0.628725 -0.032632</pose>
          <velocity>3e-05 -1e-06 7.2e-05 2.6e-05 0.000829 -4e-06</velocity>
          <acceleration>5e-06 -9e-06 1.8e-05 -0.039178 -1.20976 0.000297</acceleration>
          <wrench>1e-05 -1.6e-05 3.3e-05 0 -0 0</wrench>
        </link>
      </model>
      <light name='sun'>
        <pose frame=''>0 0 10 0 -0 0</pose>
      </light>
    </state>
    <gui fullscreen='0'>
      <camera name='user_camera'>
        <pose frame=''>5.41825 -0.16867 10.4747 -0 1.5298 -1.79034</pose>
        <view_controller>orbit</view_controller>
        <projection_type>perspective</projection_type>
      </camera>
    </gui>
    <model name='table'>
      <static>1</static>
      <link name='link'>
        <collision name='surface'>
          <pose frame=''>0 0 0.8 0 -0 0</pose>
          <geometry>
            <box>
              <size>1 0.8 0.03</size>
            </box>
          </geometry>
          <surface>
            <bounce/>
            <friction>
              <ode/>
              <torsional>
                <ode/>
              </torsional>
            </friction>
            <contact>
              <ode/>
            </contact>
          </surface>
          <max_contacts>10</max_contacts>
        </collision>
        <visual name='visual1'>
          <pose frame=''>0 0 0.8 0 -0 0</pose>
          <geometry>
            <box>
              <size>1 0.8 0.03</size>
            </box>
          </geometry>
          <material>
            <script>
              <uri>file://media/materials/scripts/gazebo.material</uri>
              <name>Gazebo/Wood</name>
            </script>
          </material>
        </visual>
        <collision name='front_left_leg'>
          <pose frame=''>0.48 0.38 0.4 0 -0 0</pose>
          <geometry>
            <cylinder>
              <radius>0.02</radius>
              <length>0.8</length>
            </cylinder>
          </geometry>
          <surface>
            <bounce/>
            <friction>
              <ode/>
              <torsional>
                <ode/>
              </torsional>
            </friction>
            <contact>
              <ode/>
            </contact>
          </surface>
          <max_contacts>10</max_contacts>
        </collision>
        <visual name='front_left_leg'>
          <pose frame=''>0.48 0.38 0.4 0 -0 0</pose>
          <geometry>
            <cylinder>
              <radius>0.02</radius>
              <length>0.8</length>
            </cylinder>
          </geometry>
          <material>
            <script>
              <uri>file://media/materials/scripts/gazebo.material</uri>
              <name>Gazebo/Grey</name>
            </script>
          </material>
        </visual>
        <collision name='front_right_leg'>
          <pose frame=''>0.48 -0.38 0.4 0 -0 0</pose>
          <geometry>
            <cylinder>
              <radius>0.02</radius>
              <length>0.8</length>
            </cylinder>
          </geometry>
          <surface>
            <bounce/>
            <friction>
              <ode/>
              <torsional>
                <ode/>
              </torsional>
            </friction>
            <contact>
              <ode/>
            </contact>
          </surface>
          <max_contacts>10</max_contacts>
        </collision>
        <visual name='front_right_leg'>
          <pose frame=''>0.48 -0.38 0.4 0 -0 0</pose>
          <geometry>
            <cylinder>
              <radius>0.02</radius>
              <length>0.8</length>
            </cylinder>
          </geometry>
          <material>
            <script>
              <uri>file://media/materials/scripts/gazebo.material</uri>
              <name>Gazebo/Grey</name>
            </script>
          </material>
        </visual>
        <collision name='back_right_leg'>
          <pose frame=''>-0.48 -0.38 0.4 0 -0 0</pose>
          <geometry>
            <cylinder>
              <radius>0.02</radius>
              <length>0.8</length>
            </cylinder>
          </geometry>
          <surface>
            <bounce/>
            <friction>
              <ode/>
              <torsional>
                <ode/>
              </torsional>
            </friction>
            <contact>
              <ode/>
            </contact>
          </surface>
          <max_contacts>10</max_contacts>
        </collision>
        <visual name='back_right_leg'>
          <pose frame=''>-0.48 -0.38 0.4 0 -0 0</pose>
          <geometry>
            <cylinder>
              <radius>0.02</radius>
              <length>0.8</length>
            </cylinder>
          </geometry>
          <material>
            <script>
              <uri>file://media/materials/scripts/gazebo.material</uri>
              <name>Gazebo/Grey</name>
            </script>
          </material>
        </visual>
        <collision name='back_left_leg'>
          <pose frame=''>-0.48 0.38 0.4 0 -0 0</pose>
          <geometry>
            <cylinder>
              <radius>0.02</radius>
              <length>0.8</length>
            </cylinder>
          </geometry>
          <surface>
            <bounce/>
            <friction>
              <ode/>
              <torsional>
                <ode/>
              </torsional>
            </friction>
            <contact>
              <ode/>
            </contact>
          </surface>
          <max_contacts>10</max_contacts>
        </collision>
        <visual name='back_left_leg'>
          <pose frame=''>-0.48 0.38 0.4 0 -0 0</pose>
          <geometry>
            <cylinder>
              <radius>0.02</radius>
              <length>0.8</length>
            </cylinder>
          </geometry>
          <material>
            <script>
              <uri>file://media/materials/scripts/gazebo.material</uri>
              <name>Gazebo/Grey</name>
            </script>
          </material>
        </visual>
        <velocity_decay>
          <linear>0</linear>
          <angular>0</angular>
        </velocity_decay>
        <self_collide>0</self_collide>
        <kinematic>0</kinematic>
        <gravity>1</gravity>
      </link>
      <pose frame=''>2.0507 -1.42427 0 0 -0 0</pose>
    </model>
    <model name='table_0'>
      <static>1</static>
      <link name='link'>
        <collision name='surface'>
          <pose frame=''>0 0 0.8 0 -0 0</pose>
          <geometry>
            <box>
              <size>1 0.8 0.03</size>
            </box>
          </geometry>
          <surface>
            <bounce/>
            <friction>
              <ode/>
              <torsional>
                <ode/>
              </torsional>
            </friction>
            <contact>
              <ode/>
            </contact>
          </surface>
          <max_contacts>10</max_contacts>
        </collision>
        <visual name='visual1'>
          <pose frame=''>0 0 0.8 0 -0 0</pose>
          <geometry>
            <box>
              <size>1 0.8 0.03</size>
            </box>
          </geometry>
          <material>
            <script>
              <uri>file://media/materials/scripts/gazebo.material</uri>
              <name>Gazebo/Wood</name>
            </script>
          </material>
        </visual>
        <collision name='front_left_leg'>
          <pose frame=''>0.48 0.38 0.4 0 -0 0</pose>
          <geometry>
            <cylinder>
              <radius>0.02</radius>
              <length>0.8</length>
            </cylinder>
          </geometry>
          <surface>
            <bounce/>
            <friction>
              <ode/>
              <torsional>
                <ode/>
              </torsional>
            </friction>
            <contact>
              <ode/>
            </contact>
          </surface>
          <max_contacts>10</max_contacts>
        </collision>
        <visual name='front_left_leg'>
          <pose frame=''>0.48 0.38 0.4 0 -0 0</pose>
          <geometry>
            <cylinder>
              <radius>0.02</radius>
              <length>0.8</length>
            </cylinder>
          </geometry>
          <material>
            <script>
              <uri>file://media/materials/scripts/gazebo.material</uri>
              <name>Gazebo/Grey</name>
            </script>
          </material>
        </visual>
        <collision name='front_right_leg'>
          <pose frame=''>0.48 -0.38 0.4 0 -0 0</pose>
          <geometry>
            <cylinder>
              <radius>0.02</radius>
              <length>0.8</length>
            </cylinder>
          </geometry>
          <surface>
            <bounce/>
            <friction>
              <ode/>
              <torsional>
                <ode/>
              </torsional>
            </friction>
            <contact>
              <ode/>
            </contact>
          </surface>
          <max_contacts>10</max_contacts>
        </collision>
        <visual name='front_right_leg'>
          <pose frame=''>0.48 -0.38 0.4 0 -0 0</pose>
          <geometry>
            <cylinder>
              <radius>0.02</radius>
              <length>0.8</length>
            </cylinder>
          </geometry>
          <material>
            <script>
              <uri>file://media/materials/scripts/gazebo.material</uri>
              <name>Gazebo/Grey</name>
            </script>
          </material>
        </visual>
        <collision name='back_right_leg'>
          <pose frame=''>-0.48 -0.38 0.4 0 -0 0</pose>
          <geometry>
            <cylinder>
              <radius>0.02</radius>
              <length>0.8</length>
            </cylinder>
          </geometry>
          <surface>
            <bounce/>
            <friction>
              <ode/>
              <torsional>
                <ode/>
              </torsional>
            </friction>
            <contact>
              <ode/>
            </contact>
          </surface>
          <max_contacts>10</max_contacts>
        </collision>
        <visual name='back_right_leg'>
          <pose frame=''>-0.48 -0.38 0.4 0 -0 0</pose>
          <geometry>
            <cylinder>
              <radius>0.02</radius>
              <length>0.8</length>
            </cylinder>
          </geometry>
          <material>
            <script>
              <uri>file://media/materials/scripts/gazebo.material</uri>
              <name>Gazebo/Grey</name>
            </script>
          </material>
        </visual>
        <collision name='back_left_leg'>
          <pose frame=''>-0.48 0.38 0.4 0 -0 0</pose>
          <geometry>
            <cylinder>
              <radius>0.02</radius>
              <length>0.8</length>
            </cylinder>
          </geometry>
          <surface>
            <bounce/>
            <friction>
              <ode/>
              <torsional>
                <ode/>
              </torsional>
            </friction>
            <contact>
              <ode/>
            </contact>
          </surface>
          <max_contacts>10</max_contacts>
        </collision>
        <visual name='back_left_leg'>
          <pose frame=''>-0.48 0.38 0.4 0 -0 0</pose>
          <geometry>
            <cylinder>
              <radius>0.02</radius>
              <length>0.8</length>
            </cylinder>
          </geometry>
          <material>
            <script>
              <uri>file://media/materials/scripts/gazebo.material</uri>
              <name>Gazebo/Grey</name>
            </script>
          </material>
        </visual>
        <velocity_decay>
          <linear>0</linear>
          <angular>0</angular>
        </velocity_decay>
        <self_collide>0</self_collide>
        <kinematic>0</kinematic>
        <gravity>1</gravity>
      </link>
      <pose frame=''>3.96378 -1.42026 0 0 -0 0</pose>
    </model>
    <model name='table_1'>
      <static>1</static>
      <link name='link'>
        <collision name='surface'>
          <pose frame=''>0 0 0.8 0 -0 0</pose>
          <geometry>
            <box>
              <size>1 0.8 0.03</size>
            </box>
          </geometry>
          <surface>
            <bounce/>
            <friction>
              <ode/>
              <torsional>
                <ode/>
              </torsional>
            </friction>
            <contact>
              <ode/>
            </contact>
          </surface>
          <max_contacts>10</max_contacts>
        </collision>
        <visual name='visual1'>
          <pose frame=''>0 0 0.8 0 -0 0</pose>
          <geometry>
            <box>
              <size>1 0.8 0.03</size>
            </box>
          </geometry>
          <material>
            <script>
              <uri>file://media/materials/scripts/gazebo.material</uri>
              <name>Gazebo/Wood</name>
            </script>
          </material>
        </visual>
        <collision name='front_left_leg'>
          <pose frame=''>0.48 0.38 0.4 0 -0 0</pose>
          <geometry>
            <cylinder>
              <radius>0.02</radius>
              <length>0.8</length>
            </cylinder>
          </geometry>
          <surface>
            <bounce/>
            <friction>
              <ode/>
              <torsional>
                <ode/>
              </torsional>
            </friction>
            <contact>
              <ode/>
            </contact>
          </surface>
          <max_contacts>10</max_contacts>
        </collision>
        <visual name='front_left_leg'>
          <pose frame=''>0.48 0.38 0.4 0 -0 0</pose>
          <geometry>
            <cylinder>
              <radius>0.02</radius>
              <length>0.8</length>
            </cylinder>
          </geometry>
          <material>
            <script>
              <uri>file://media/materials/scripts/gazebo.material</uri>
              <name>Gazebo/Grey</name>
            </script>
          </material>
        </visual>
        <collision name='front_right_leg'>
          <pose frame=''>0.48 -0.38 0.4 0 -0 0</pose>
          <geometry>
            <cylinder>
              <radius>0.02</radius>
              <length>0.8</length>
            </cylinder>
          </geometry>
          <surface>
            <bounce/>
            <friction>
              <ode/>
              <torsional>
                <ode/>
              </torsional>
            </friction>
            <contact>
              <ode/>
            </contact>
          </surface>
          <max_contacts>10</max_contacts>
        </collision>
        <visual name='front_right_leg'>
          <pose frame=''>0.48 -0.38 0.4 0 -0 0</pose>
          <geometry>
            <cylinder>
              <radius>0.02</radius>
              <length>0.8</length>
            </cylinder>
          </geometry>
          <material>
            <script>
              <uri>file://media/materials/scripts/gazebo.material</uri>
              <name>Gazebo/Grey</name>
            </script>
          </material>
        </visual>
        <collision name='back_right_leg'>
          <pose frame=''>-0.48 -0.38 0.4 0 -0 0</pose>
          <geometry>
            <cylinder>
              <radius>0.02</radius>
              <length>0.8</length>
            </cylinder>
          </geometry>
          <surface>
            <bounce/>
            <friction>
              <ode/>
              <torsional>
                <ode/>
              </torsional>
            </friction>
            <contact>
              <ode/>
            </contact>
          </surface>
          <max_contacts>10</max_contacts>
        </collision>
        <visual name='back_right_leg'>
          <pose frame=''>-0.48 -0.38 0.4 0 -0 0</pose>
          <geometry>
            <cylinder>
              <radius>0.02</radius>
              <length>0.8</length>
            </cylinder>
          </geometry>
          <material>
            <script>
              <uri>file://media/materials/scripts/gazebo.material</uri>
              <name>Gazebo/Grey</name>
            </script>
          </material>
        </visual>
        <collision name='back_left_leg'>
          <pose frame=''>-0.48 0.38 0.4 0 -0 0</pose>
          <geometry>
            <cylinder>
              <radius>0.02</radius>
              <length>0.8</length>
            </cylinder>
          </geometry>
          <surface>
            <bounce/>
            <friction>
              <ode/>
              <torsional>
                <ode/>
              </torsional>
            </friction>
            <contact>
              <ode/>
            </contact>
          </surface>
          <max_contacts>10</max_contacts>
        </collision>
        <visual name='back_left_leg'>
          <pose frame=''>-0.48 0.38 0.4 0 -0 0</pose>
          <geometry>
            <cylinder>
              <radius>0.02</radius>
              <length>0.8</length>
            </cylinder>
          </geometry>
          <material>
            <script>
              <uri>file://media/materials/scripts/gazebo.material</uri>
              <name>Gazebo/Grey</name>
            </script>
          </material>
        </visual>
        <velocity_decay>
          <linear>0</linear>
          <angular>0</angular>
        </velocity_decay>
        <self_collide>0</self_collide>
        <kinematic>0</kinematic>
        <gravity>1</gravity>
      </link>
      <pose frame=''>5.96985 -1.37487 0 0 -0 0</pose>
    </model>
    <model name='aruco_marker_original_582_clone'>
      <static>0</static>
      <link name='marker'>
        <inertial>
          <mass>0.1</mass>
          <inertia>
            <ixx>0</ixx>
            <ixy>0</ixy>
            <ixz>0</ixz>
            <iyy>0</iyy>
            <iyz>0</iyz>
            <izz>0</izz>
          </inertia>
        </inertial>
        <visual name='visual'>
          <pose frame=''>0 0 0 0 -0 1.57</pose>
          <geometry>
            <box>
              <size>0.16 0.16 0.001</size>
            </box>
          </geometry>
          <material>
            <script>
              <uri>model://aruco_marker_original_582/material/scripts</uri>
              <uri>model://aruco_marker_original_582/material/textures</uri>
              <name>Aruco/aruco_marker_original_582</name>
            </script>
          </material>
        </visual>
        <collision name='collision'>
          <geometry>
            <box>
              <size>0.16 0.16 0.001</size>
            </box>
          </geometry>
          <surface>
            <bounce/>
            <friction>
              <ode/>
              <torsional>
                <ode/>
              </torsional>
            </friction>
            <contact>
              <ode/>
            </contact>
          </surface>
          <max_contacts>10</max_contacts>
        </collision>
        <self_collide>1</self_collide>
        <kinematic>0</kinematic>
        <gravity>1</gravity>
      </link>
      <pose frame=''>2.04717 -1.0994 0.0005 4e-06 1e-06 0</pose>
    </model>
    <model name='aruco_marker_original_26'>
      <static>0</static>
      <link name='marker'>
        <inertial>
          <mass>0.1</mass>
          <inertia>
            <ixx>0</ixx>
            <ixy>0</ixy>
            <ixz>0</ixz>
            <iyy>0</iyy>
            <iyz>0</iyz>
            <izz>0</izz>
          </inertia>
        </inertial>
        <visual name='visual'>
          <pose frame=''>0 0 0 0 -0 1.57</pose>
          <geometry>
            <box>
              <size>0.16 0.16 0.001</size>
            </box>
          </geometry>
          <material>
            <script>
              <uri>model://aruco_marker_original_26/material/scripts</uri>
              <uri>model://aruco_marker_original_26/material/textures</uri>
              <name>Aruco/aruco_marker_original_26</name>
            </script>
          </material>
        </visual>
        <collision name='collision'>
          <geometry>
            <box>
              <size>0.16 0.16 0.001</size>
            </box>
          </geometry>
          <surface>
            <bounce/>
            <friction>
              <ode/>
              <torsional>
                <ode/>
              </torsional>
            </friction>
            <contact>
              <ode/>
            </contact>
          </surface>
          <max_contacts>10</max_contacts>
        </collision>
        <self_collide>1</self_collide>
        <kinematic>0</kinematic>
        <gravity>1</gravity>
      </link>
      <pose frame=''>4.00332 -0.010936 0 0 -0 0</pose>
    </model>
    <model name='aruco_marker_original_26_clone'>
      <static>0</static>
      <link name='marker'>
        <inertial>
          <mass>0.1</mass>
          <inertia>
            <ixx>0</ixx>
            <ixy>0</ixy>
            <ixz>0</ixz>
            <iyy>0</iyy>
            <iyz>0</iyz>
            <izz>0</izz>
          </inertia>
        </inertial>
        <visual name='visual'>
          <pose frame=''>0 0 0 0 -0 1.57</pose>
          <geometry>
            <box>
              <size>0.16 0.16 0.001</size>
            </box>
          </geometry>
          <material>
            <script>
              <uri>model://aruco_marker_original_26/material/scripts</uri>
              <uri>model://aruco_marker_original_26/material/textures</uri>
              <name>Aruco/aruco_marker_original_26</name>
            </script>
          </material>
        </visual>
        <collision name='collision'>
          <geometry>
            <box>
              <size>0.16 0.16 0.001</size>
            </box>
          </geometry>
          <surface>
            <bounce/>
            <friction>
              <ode/>
              <torsional>
                <ode/>
              </torsional>
            </friction>
            <contact>
              <ode/>
            </contact>
          </surface>
          <max_contacts>10</max_contacts>
        </collision>
        <self_collide>1</self_collide>
        <kinematic>0</kinematic>
        <gravity>1</gravity>
      </link>
      <pose frame=''>3.99514 -0.753102 0.0005 0 -1e-06 0</pose>
    </model>
    <model name='aruco_marker_original_63'>
      <static>0</static>
      <link name='marker'>
        <inertial>
          <mass>0.1</mass>
          <inertia>
            <ixx>0</ixx>
            <ixy>0</ixy>
            <ixz>0</ixz>
            <iyy>0</iyy>
            <iyz>0</iyz>
            <izz>0</izz>
          </inertia>
        </inertial>
        <visual name='visual'>
          <pose frame=''>0 0 0 0 -0 1.57</pose>
          <geometry>
            <box>
              <size>0.16 0.16 0.001</size>
            </box>
          </geometry>
          <material>
            <script>
              <uri>model://aruco_marker_original_63/material/scripts</uri>
              <uri>model://aruco_marker_original_63/material/textures</uri>
              <name>Aruco/aruco_marker_original_63</name>
            </script>
          </material>
        </visual>
        <collision name='collision'>
          <geometry>
            <box>
              <size>0.16 0.16 0.001</size>
            </box>
          </geometry>
          <surface>
            <bounce/>
            <friction>
              <ode/>
              <torsional>
                <ode/>
              </torsional>
            </friction>
            <contact>
              <ode/>
            </contact>
          </surface>
          <max_contacts>10</max_contacts>
        </collision>
        <self_collide>1</self_collide>
        <kinematic>0</kinematic>
        <gravity>1</gravity>
      </link>
      <pose frame=''>5.76871 0.028719 0 0 -0 0</pose>
    </model>
    <model name='aruco_marker_original_63_clone'>
      <static>0</static>
      <link name='marker'>
        <inertial>
          <mass>0.1</mass>
          <inertia>
            <ixx>0</ixx>
            <ixy>0</ixy>
            <ixz>0</ixz>
            <iyy>0</iyy>
            <iyz>0</iyz>
            <izz>0</izz>
          </inertia>
        </inertial>
        <visual name='visual'>
          <pose frame=''>0 0 0 0 -0 1.57</pose>
          <geometry>
            <box>
              <size>0.16 0.16 0.001</size>
            </box>
          </geometry>
          <material>
            <script>
              <uri>model://aruco_marker_original_63/material/scripts</uri>
              <uri>model://aruco_marker_original_63/material/textures</uri>
              <name>Aruco/aruco_marker_original_63</name>
            </script>
          </material>
        </visual>
        <collision name='collision'>
          <geometry>
            <box>
              <size>0.16 0.16 0.001</size>
            </box>
          </geometry>
          <surface>
            <bounce/>
            <friction>
              <ode/>
              <torsional>
                <ode/>
              </torsional>
            </friction>
            <contact>
              <ode/>
            </contact>
          </surface>
          <max_contacts>10</max_contacts>
        </collision>
        <self_collide>1</self_collide>
        <kinematic>0</kinematic>
        <gravity>1</gravity>
      </link>
      <pose frame=''>5.86754 -0.370933 0.000501 5e-06 1e-06 0</pose>
    </model>
  </world>
</sdf>
